{
  "cells": [
    {
      "cell_type": "code",
      "execution_count": null,
      "metadata": {
        "colab": {
          "background_save": true
        },
        "id": "1df61d99-af72-4f49-a6e2-fb06e2a05735",
        "outputId": "50bb926e-377c-4517-d05f-3fcad1c67991"
      },
      "outputs": [
        {
          "name": "stderr",
          "output_type": "stream",
          "text": [
            "ERROR:root:Internal Python error in the inspect module.\n",
            "Below is the traceback from this internal error.\n",
            "\n",
            "ERROR:root:Internal Python error in the inspect module.\n",
            "Below is the traceback from this internal error.\n",
            "\n",
            "ERROR:root:Internal Python error in the inspect module.\n",
            "Below is the traceback from this internal error.\n",
            "\n"
          ]
        },
        {
          "name": "stdout",
          "output_type": "stream",
          "text": [
            "Traceback (most recent call last):\n",
            "  File \"/usr/local/lib/python3.10/dist-packages/IPython/core/interactiveshell.py\", line 3553, in run_code\n",
            "    exec(code_obj, self.user_global_ns, self.user_ns)\n",
            "  File \"<ipython-input-9-7dd3504c366f>\", line 1, in <cell line: 1>\n",
            "    import pandas as pd\n",
            "  File \"<frozen importlib._bootstrap>\", line 1027, in _find_and_load\n",
            "  File \"<frozen importlib._bootstrap>\", line 1002, in _find_and_load_unlocked\n",
            "  File \"<frozen importlib._bootstrap>\", line 945, in _find_spec\n",
            "  File \"<frozen importlib._bootstrap_external>\", line 1439, in find_spec\n",
            "  File \"<frozen importlib._bootstrap_external>\", line 1408, in _get_spec\n",
            "  File \"<frozen importlib._bootstrap_external>\", line 1366, in _path_importer_cache\n",
            "OSError: [Errno 107] Transport endpoint is not connected\n",
            "\n",
            "During handling of the above exception, another exception occurred:\n",
            "\n",
            "Traceback (most recent call last):\n",
            "  File \"/usr/local/lib/python3.10/dist-packages/IPython/core/interactiveshell.py\", line 2099, in showtraceback\n",
            "    stb = value._render_traceback_()\n",
            "AttributeError: 'OSError' object has no attribute '_render_traceback_'\n",
            "\n",
            "During handling of the above exception, another exception occurred:\n",
            "\n",
            "Traceback (most recent call last):\n",
            "  File \"/usr/local/lib/python3.10/dist-packages/IPython/core/ultratb.py\", line 1101, in get_records\n",
            "    return _fixed_getinnerframes(etb, number_of_lines_of_context, tb_offset)\n",
            "  File \"/usr/local/lib/python3.10/dist-packages/IPython/core/ultratb.py\", line 248, in wrapped\n",
            "    return f(*args, **kwargs)\n",
            "  File \"/usr/local/lib/python3.10/dist-packages/IPython/core/ultratb.py\", line 281, in _fixed_getinnerframes\n",
            "    records = fix_frame_records_filenames(inspect.getinnerframes(etb, context))\n",
            "  File \"/usr/lib/python3.10/inspect.py\", line 1662, in getinnerframes\n",
            "    frameinfo = (tb.tb_frame,) + getframeinfo(tb, context)\n",
            "  File \"/usr/lib/python3.10/inspect.py\", line 1620, in getframeinfo\n",
            "    filename = getsourcefile(frame) or getfile(frame)\n",
            "  File \"/usr/lib/python3.10/inspect.py\", line 829, in getsourcefile\n",
            "    module = getmodule(object, filename)\n",
            "  File \"/usr/lib/python3.10/inspect.py\", line 861, in getmodule\n",
            "    file = getabsfile(object, _filename)\n",
            "  File \"/usr/lib/python3.10/inspect.py\", line 845, in getabsfile\n",
            "    return os.path.normcase(os.path.abspath(_filename))\n",
            "  File \"/usr/lib/python3.10/posixpath.py\", line 384, in abspath\n",
            "    cwd = os.getcwd()\n",
            "OSError: [Errno 107] Transport endpoint is not connected\n",
            "Traceback (most recent call last):\n",
            "  File \"/usr/local/lib/python3.10/dist-packages/IPython/core/interactiveshell.py\", line 3553, in run_code\n",
            "    exec(code_obj, self.user_global_ns, self.user_ns)\n",
            "  File \"<ipython-input-9-7dd3504c366f>\", line 1, in <cell line: 1>\n",
            "    import pandas as pd\n",
            "  File \"<frozen importlib._bootstrap>\", line 1027, in _find_and_load\n",
            "  File \"<frozen importlib._bootstrap>\", line 1002, in _find_and_load_unlocked\n",
            "  File \"<frozen importlib._bootstrap>\", line 945, in _find_spec\n",
            "  File \"<frozen importlib._bootstrap_external>\", line 1439, in find_spec\n",
            "  File \"<frozen importlib._bootstrap_external>\", line 1408, in _get_spec\n",
            "  File \"<frozen importlib._bootstrap_external>\", line 1366, in _path_importer_cache\n",
            "OSError: [Errno 107] Transport endpoint is not connected\n",
            "\n",
            "During handling of the above exception, another exception occurred:\n",
            "\n",
            "Traceback (most recent call last):\n",
            "  File \"/usr/local/lib/python3.10/dist-packages/IPython/core/interactiveshell.py\", line 2099, in showtraceback\n",
            "    stb = value._render_traceback_()\n",
            "AttributeError: 'OSError' object has no attribute '_render_traceback_'\n",
            "\n",
            "During handling of the above exception, another exception occurred:\n",
            "\n",
            "Traceback (most recent call last):\n",
            "  File \"/usr/local/lib/python3.10/dist-packages/IPython/core/interactiveshell.py\", line 3473, in run_ast_nodes\n",
            "    if (await self.run_code(code, result,  async_=asy)):\n",
            "  File \"/usr/local/lib/python3.10/dist-packages/IPython/core/interactiveshell.py\", line 3575, in run_code\n",
            "    self.showtraceback(running_compiled_code=True)\n",
            "  File \"/usr/local/lib/python3.10/dist-packages/IPython/core/interactiveshell.py\", line 2101, in showtraceback\n",
            "    stb = self.InteractiveTB.structured_traceback(etype,\n",
            "  File \"/usr/local/lib/python3.10/dist-packages/IPython/core/ultratb.py\", line 1367, in structured_traceback\n",
            "    return FormattedTB.structured_traceback(\n",
            "  File \"/usr/local/lib/python3.10/dist-packages/IPython/core/ultratb.py\", line 1267, in structured_traceback\n",
            "    return VerboseTB.structured_traceback(\n",
            "  File \"/usr/local/lib/python3.10/dist-packages/IPython/core/ultratb.py\", line 1124, in structured_traceback\n",
            "    formatted_exception = self.format_exception_as_a_whole(etype, evalue, etb, number_of_lines_of_context,\n",
            "  File \"/usr/local/lib/python3.10/dist-packages/IPython/core/ultratb.py\", line 1082, in format_exception_as_a_whole\n",
            "    last_unique, recursion_repeat = find_recursion(orig_etype, evalue, records)\n",
            "  File \"/usr/local/lib/python3.10/dist-packages/IPython/core/ultratb.py\", line 382, in find_recursion\n",
            "    return len(records), 0\n",
            "TypeError: object of type 'NoneType' has no len()\n",
            "\n",
            "During handling of the above exception, another exception occurred:\n",
            "\n",
            "Traceback (most recent call last):\n",
            "  File \"/usr/local/lib/python3.10/dist-packages/IPython/core/interactiveshell.py\", line 2099, in showtraceback\n",
            "    stb = value._render_traceback_()\n",
            "AttributeError: 'TypeError' object has no attribute '_render_traceback_'\n",
            "\n",
            "During handling of the above exception, another exception occurred:\n",
            "\n",
            "Traceback (most recent call last):\n",
            "  File \"/usr/local/lib/python3.10/dist-packages/IPython/core/ultratb.py\", line 1101, in get_records\n",
            "    return _fixed_getinnerframes(etb, number_of_lines_of_context, tb_offset)\n",
            "  File \"/usr/local/lib/python3.10/dist-packages/IPython/core/ultratb.py\", line 248, in wrapped\n",
            "    return f(*args, **kwargs)\n",
            "  File \"/usr/local/lib/python3.10/dist-packages/IPython/core/ultratb.py\", line 281, in _fixed_getinnerframes\n",
            "    records = fix_frame_records_filenames(inspect.getinnerframes(etb, context))\n",
            "  File \"/usr/lib/python3.10/inspect.py\", line 1662, in getinnerframes\n",
            "    frameinfo = (tb.tb_frame,) + getframeinfo(tb, context)\n",
            "  File \"/usr/lib/python3.10/inspect.py\", line 1620, in getframeinfo\n",
            "    filename = getsourcefile(frame) or getfile(frame)\n",
            "  File \"/usr/lib/python3.10/inspect.py\", line 829, in getsourcefile\n",
            "    module = getmodule(object, filename)\n",
            "  File \"/usr/lib/python3.10/inspect.py\", line 861, in getmodule\n",
            "    file = getabsfile(object, _filename)\n",
            "  File \"/usr/lib/python3.10/inspect.py\", line 845, in getabsfile\n",
            "    return os.path.normcase(os.path.abspath(_filename))\n",
            "  File \"/usr/lib/python3.10/posixpath.py\", line 384, in abspath\n",
            "    cwd = os.getcwd()\n",
            "OSError: [Errno 107] Transport endpoint is not connected\n",
            "Traceback (most recent call last):\n",
            "  File \"/usr/local/lib/python3.10/dist-packages/IPython/core/interactiveshell.py\", line 3553, in run_code\n",
            "    exec(code_obj, self.user_global_ns, self.user_ns)\n",
            "  File \"<ipython-input-9-7dd3504c366f>\", line 1, in <cell line: 1>\n",
            "    import pandas as pd\n",
            "  File \"<frozen importlib._bootstrap>\", line 1027, in _find_and_load\n",
            "  File \"<frozen importlib._bootstrap>\", line 1002, in _find_and_load_unlocked\n",
            "  File \"<frozen importlib._bootstrap>\", line 945, in _find_spec\n",
            "  File \"<frozen importlib._bootstrap_external>\", line 1439, in find_spec\n",
            "  File \"<frozen importlib._bootstrap_external>\", line 1408, in _get_spec\n",
            "  File \"<frozen importlib._bootstrap_external>\", line 1366, in _path_importer_cache\n",
            "OSError: [Errno 107] Transport endpoint is not connected\n",
            "\n",
            "During handling of the above exception, another exception occurred:\n",
            "\n",
            "Traceback (most recent call last):\n",
            "  File \"/usr/local/lib/python3.10/dist-packages/IPython/core/interactiveshell.py\", line 2099, in showtraceback\n",
            "    stb = value._render_traceback_()\n",
            "AttributeError: 'OSError' object has no attribute '_render_traceback_'\n",
            "\n",
            "During handling of the above exception, another exception occurred:\n",
            "\n",
            "Traceback (most recent call last):\n",
            "  File \"/usr/local/lib/python3.10/dist-packages/IPython/core/interactiveshell.py\", line 3473, in run_ast_nodes\n",
            "    if (await self.run_code(code, result,  async_=asy)):\n",
            "  File \"/usr/local/lib/python3.10/dist-packages/IPython/core/interactiveshell.py\", line 3575, in run_code\n",
            "    self.showtraceback(running_compiled_code=True)\n",
            "  File \"/usr/local/lib/python3.10/dist-packages/IPython/core/interactiveshell.py\", line 2101, in showtraceback\n",
            "    stb = self.InteractiveTB.structured_traceback(etype,\n",
            "  File \"/usr/local/lib/python3.10/dist-packages/IPython/core/ultratb.py\", line 1367, in structured_traceback\n",
            "    return FormattedTB.structured_traceback(\n",
            "  File \"/usr/local/lib/python3.10/dist-packages/IPython/core/ultratb.py\", line 1267, in structured_traceback\n",
            "    return VerboseTB.structured_traceback(\n",
            "  File \"/usr/local/lib/python3.10/dist-packages/IPython/core/ultratb.py\", line 1124, in structured_traceback\n",
            "    formatted_exception = self.format_exception_as_a_whole(etype, evalue, etb, number_of_lines_of_context,\n",
            "  File \"/usr/local/lib/python3.10/dist-packages/IPython/core/ultratb.py\", line 1082, in format_exception_as_a_whole\n",
            "    last_unique, recursion_repeat = find_recursion(orig_etype, evalue, records)\n",
            "  File \"/usr/local/lib/python3.10/dist-packages/IPython/core/ultratb.py\", line 382, in find_recursion\n",
            "    return len(records), 0\n",
            "TypeError: object of type 'NoneType' has no len()\n",
            "\n",
            "During handling of the above exception, another exception occurred:\n",
            "\n",
            "Traceback (most recent call last):\n",
            "  File \"/usr/local/lib/python3.10/dist-packages/IPython/core/interactiveshell.py\", line 2099, in showtraceback\n",
            "    stb = value._render_traceback_()\n",
            "AttributeError: 'TypeError' object has no attribute '_render_traceback_'\n",
            "\n",
            "During handling of the above exception, another exception occurred:\n",
            "\n",
            "Traceback (most recent call last):\n",
            "  File \"/usr/local/lib/python3.10/dist-packages/IPython/core/interactiveshell.py\", line 3030, in _run_cell\n",
            "    return runner(coro)\n",
            "  File \"/usr/local/lib/python3.10/dist-packages/IPython/core/async_helpers.py\", line 78, in _pseudo_sync_runner\n",
            "    coro.send(None)\n",
            "  File \"/usr/local/lib/python3.10/dist-packages/IPython/core/interactiveshell.py\", line 3257, in run_cell_async\n",
            "    has_raised = await self.run_ast_nodes(code_ast.body, cell_name,\n",
            "  File \"/usr/local/lib/python3.10/dist-packages/IPython/core/interactiveshell.py\", line 3492, in run_ast_nodes\n",
            "    self.showtraceback()\n",
            "  File \"/usr/local/lib/python3.10/dist-packages/IPython/core/interactiveshell.py\", line 2101, in showtraceback\n",
            "    stb = self.InteractiveTB.structured_traceback(etype,\n",
            "  File \"/usr/local/lib/python3.10/dist-packages/IPython/core/ultratb.py\", line 1367, in structured_traceback\n",
            "    return FormattedTB.structured_traceback(\n",
            "  File \"/usr/local/lib/python3.10/dist-packages/IPython/core/ultratb.py\", line 1267, in structured_traceback\n",
            "    return VerboseTB.structured_traceback(\n",
            "  File \"/usr/local/lib/python3.10/dist-packages/IPython/core/ultratb.py\", line 1142, in structured_traceback\n",
            "    formatted_exceptions += self.format_exception_as_a_whole(etype, evalue, etb, lines_of_context,\n",
            "  File \"/usr/local/lib/python3.10/dist-packages/IPython/core/ultratb.py\", line 1082, in format_exception_as_a_whole\n",
            "    last_unique, recursion_repeat = find_recursion(orig_etype, evalue, records)\n",
            "  File \"/usr/local/lib/python3.10/dist-packages/IPython/core/ultratb.py\", line 382, in find_recursion\n",
            "    return len(records), 0\n",
            "TypeError: object of type 'NoneType' has no len()\n",
            "\n",
            "During handling of the above exception, another exception occurred:\n",
            "\n",
            "Traceback (most recent call last):\n",
            "  File \"/usr/local/lib/python3.10/dist-packages/IPython/core/interactiveshell.py\", line 2099, in showtraceback\n",
            "    stb = value._render_traceback_()\n",
            "AttributeError: 'TypeError' object has no attribute '_render_traceback_'\n",
            "\n",
            "During handling of the above exception, another exception occurred:\n",
            "\n",
            "Traceback (most recent call last):\n",
            "  File \"/usr/local/lib/python3.10/dist-packages/IPython/core/ultratb.py\", line 1101, in get_records\n",
            "    return _fixed_getinnerframes(etb, number_of_lines_of_context, tb_offset)\n",
            "  File \"/usr/local/lib/python3.10/dist-packages/IPython/core/ultratb.py\", line 248, in wrapped\n",
            "    return f(*args, **kwargs)\n",
            "  File \"/usr/local/lib/python3.10/dist-packages/IPython/core/ultratb.py\", line 281, in _fixed_getinnerframes\n",
            "    records = fix_frame_records_filenames(inspect.getinnerframes(etb, context))\n",
            "  File \"/usr/lib/python3.10/inspect.py\", line 1662, in getinnerframes\n",
            "    frameinfo = (tb.tb_frame,) + getframeinfo(tb, context)\n",
            "  File \"/usr/lib/python3.10/inspect.py\", line 1620, in getframeinfo\n",
            "    filename = getsourcefile(frame) or getfile(frame)\n",
            "  File \"/usr/lib/python3.10/inspect.py\", line 829, in getsourcefile\n",
            "    module = getmodule(object, filename)\n",
            "  File \"/usr/lib/python3.10/inspect.py\", line 861, in getmodule\n",
            "    file = getabsfile(object, _filename)\n",
            "  File \"/usr/lib/python3.10/inspect.py\", line 845, in getabsfile\n",
            "    return os.path.normcase(os.path.abspath(_filename))\n",
            "  File \"/usr/lib/python3.10/posixpath.py\", line 384, in abspath\n",
            "    cwd = os.getcwd()\n",
            "OSError: [Errno 107] Transport endpoint is not connected\n"
          ]
        }
      ],
      "source": [
        "import pandas as pd"
      ],
      "id": "1df61d99-af72-4f49-a6e2-fb06e2a05735"
    },
    {
      "cell_type": "code",
      "execution_count": null,
      "metadata": {
        "colab": {
          "base_uri": "https://localhost:8080/"
        },
        "id": "_ihmFEU6yfrq",
        "outputId": "624e615d-d8c3-419c-d32d-00f97cb52510"
      },
      "outputs": [
        {
          "name": "stdout",
          "output_type": "stream",
          "text": [
            "Mounted at /content/drive\n"
          ]
        }
      ],
      "source": [
        "from google.colab import drive\n",
        "drive.mount('/content/drive', force_remount=True)"
      ],
      "id": "_ihmFEU6yfrq"
    },
    {
      "cell_type": "code",
      "execution_count": null,
      "metadata": {
        "colab": {
          "background_save": true,
          "base_uri": "https://localhost:8080/",
          "height": 183
        },
        "id": "N_Nkc0z42C3l",
        "outputId": "34ed0375-dffd-4584-ade8-15d19cffcd95"
      },
      "outputs": [
        {
          "name": "stderr",
          "output_type": "stream",
          "text": [
            "ERROR:root:Internal Python error in the inspect module.\n",
            "Below is the traceback from this internal error.\n",
            "\n",
            "ERROR:root:Internal Python error in the inspect module.\n",
            "Below is the traceback from this internal error.\n",
            "\n",
            "ERROR:root:Internal Python error in the inspect module.\n",
            "Below is the traceback from this internal error.\n",
            "\n"
          ]
        },
        {
          "name": "stdout",
          "output_type": "stream",
          "text": [
            "Traceback (most recent call last):\n",
            "  File \"/usr/local/lib/python3.10/dist-packages/IPython/core/interactiveshell.py\", line 3553, in run_code\n",
            "    exec(code_obj, self.user_global_ns, self.user_ns)\n",
            "  File \"<ipython-input-10-5cd72ee79aa1>\", line 2, in <cell line: 2>\n",
            "    os.chdir(\"drive/My Drive/Project/DadosPreprocessados\")\n",
            "OSError: [Errno 107] Transport endpoint is not connected: 'drive/My Drive/Project/DadosPreprocessados'\n",
            "\n",
            "During handling of the above exception, another exception occurred:\n",
            "\n",
            "Traceback (most recent call last):\n",
            "  File \"/usr/local/lib/python3.10/dist-packages/IPython/core/interactiveshell.py\", line 2099, in showtraceback\n",
            "    stb = value._render_traceback_()\n",
            "AttributeError: 'OSError' object has no attribute '_render_traceback_'\n",
            "\n",
            "During handling of the above exception, another exception occurred:\n",
            "\n",
            "Traceback (most recent call last):\n",
            "  File \"/usr/local/lib/python3.10/dist-packages/IPython/core/ultratb.py\", line 1101, in get_records\n",
            "    return _fixed_getinnerframes(etb, number_of_lines_of_context, tb_offset)\n",
            "  File \"/usr/local/lib/python3.10/dist-packages/IPython/core/ultratb.py\", line 248, in wrapped\n",
            "    return f(*args, **kwargs)\n",
            "  File \"/usr/local/lib/python3.10/dist-packages/IPython/core/ultratb.py\", line 281, in _fixed_getinnerframes\n",
            "    records = fix_frame_records_filenames(inspect.getinnerframes(etb, context))\n",
            "  File \"/usr/lib/python3.10/inspect.py\", line 1662, in getinnerframes\n",
            "    frameinfo = (tb.tb_frame,) + getframeinfo(tb, context)\n",
            "  File \"/usr/lib/python3.10/inspect.py\", line 1620, in getframeinfo\n",
            "    filename = getsourcefile(frame) or getfile(frame)\n",
            "  File \"/usr/lib/python3.10/inspect.py\", line 829, in getsourcefile\n",
            "    module = getmodule(object, filename)\n",
            "  File \"/usr/lib/python3.10/inspect.py\", line 861, in getmodule\n",
            "    file = getabsfile(object, _filename)\n",
            "  File \"/usr/lib/python3.10/inspect.py\", line 845, in getabsfile\n",
            "    return os.path.normcase(os.path.abspath(_filename))\n",
            "  File \"/usr/lib/python3.10/posixpath.py\", line 384, in abspath\n",
            "    cwd = os.getcwd()\n",
            "OSError: [Errno 107] Transport endpoint is not connected\n",
            "Traceback (most recent call last):\n",
            "  File \"/usr/local/lib/python3.10/dist-packages/IPython/core/interactiveshell.py\", line 3553, in run_code\n",
            "    exec(code_obj, self.user_global_ns, self.user_ns)\n",
            "  File \"<ipython-input-10-5cd72ee79aa1>\", line 2, in <cell line: 2>\n",
            "    os.chdir(\"drive/My Drive/Project/DadosPreprocessados\")\n",
            "OSError: [Errno 107] Transport endpoint is not connected: 'drive/My Drive/Project/DadosPreprocessados'\n",
            "\n",
            "During handling of the above exception, another exception occurred:\n",
            "\n",
            "Traceback (most recent call last):\n",
            "  File \"/usr/local/lib/python3.10/dist-packages/IPython/core/interactiveshell.py\", line 2099, in showtraceback\n",
            "    stb = value._render_traceback_()\n",
            "AttributeError: 'OSError' object has no attribute '_render_traceback_'\n",
            "\n",
            "During handling of the above exception, another exception occurred:\n",
            "\n",
            "Traceback (most recent call last):\n",
            "  File \"/usr/local/lib/python3.10/dist-packages/IPython/core/interactiveshell.py\", line 3473, in run_ast_nodes\n",
            "    if (await self.run_code(code, result,  async_=asy)):\n",
            "  File \"/usr/local/lib/python3.10/dist-packages/IPython/core/interactiveshell.py\", line 3575, in run_code\n",
            "    self.showtraceback(running_compiled_code=True)\n",
            "  File \"/usr/local/lib/python3.10/dist-packages/IPython/core/interactiveshell.py\", line 2101, in showtraceback\n",
            "    stb = self.InteractiveTB.structured_traceback(etype,\n",
            "  File \"/usr/local/lib/python3.10/dist-packages/IPython/core/ultratb.py\", line 1367, in structured_traceback\n",
            "    return FormattedTB.structured_traceback(\n",
            "  File \"/usr/local/lib/python3.10/dist-packages/IPython/core/ultratb.py\", line 1267, in structured_traceback\n",
            "    return VerboseTB.structured_traceback(\n",
            "  File \"/usr/local/lib/python3.10/dist-packages/IPython/core/ultratb.py\", line 1124, in structured_traceback\n",
            "    formatted_exception = self.format_exception_as_a_whole(etype, evalue, etb, number_of_lines_of_context,\n",
            "  File \"/usr/local/lib/python3.10/dist-packages/IPython/core/ultratb.py\", line 1082, in format_exception_as_a_whole\n",
            "    last_unique, recursion_repeat = find_recursion(orig_etype, evalue, records)\n",
            "  File \"/usr/local/lib/python3.10/dist-packages/IPython/core/ultratb.py\", line 382, in find_recursion\n",
            "    return len(records), 0\n",
            "TypeError: object of type 'NoneType' has no len()\n",
            "\n",
            "During handling of the above exception, another exception occurred:\n",
            "\n",
            "Traceback (most recent call last):\n",
            "  File \"/usr/local/lib/python3.10/dist-packages/IPython/core/interactiveshell.py\", line 2099, in showtraceback\n",
            "    stb = value._render_traceback_()\n",
            "AttributeError: 'TypeError' object has no attribute '_render_traceback_'\n",
            "\n",
            "During handling of the above exception, another exception occurred:\n",
            "\n",
            "Traceback (most recent call last):\n",
            "  File \"/usr/local/lib/python3.10/dist-packages/IPython/core/ultratb.py\", line 1101, in get_records\n",
            "    return _fixed_getinnerframes(etb, number_of_lines_of_context, tb_offset)\n",
            "  File \"/usr/local/lib/python3.10/dist-packages/IPython/core/ultratb.py\", line 248, in wrapped\n",
            "    return f(*args, **kwargs)\n",
            "  File \"/usr/local/lib/python3.10/dist-packages/IPython/core/ultratb.py\", line 281, in _fixed_getinnerframes\n",
            "    records = fix_frame_records_filenames(inspect.getinnerframes(etb, context))\n",
            "  File \"/usr/lib/python3.10/inspect.py\", line 1662, in getinnerframes\n",
            "    frameinfo = (tb.tb_frame,) + getframeinfo(tb, context)\n",
            "  File \"/usr/lib/python3.10/inspect.py\", line 1620, in getframeinfo\n",
            "    filename = getsourcefile(frame) or getfile(frame)\n",
            "  File \"/usr/lib/python3.10/inspect.py\", line 829, in getsourcefile\n",
            "    module = getmodule(object, filename)\n",
            "  File \"/usr/lib/python3.10/inspect.py\", line 861, in getmodule\n",
            "    file = getabsfile(object, _filename)\n",
            "  File \"/usr/lib/python3.10/inspect.py\", line 845, in getabsfile\n",
            "    return os.path.normcase(os.path.abspath(_filename))\n",
            "  File \"/usr/lib/python3.10/posixpath.py\", line 384, in abspath\n",
            "    cwd = os.getcwd()\n",
            "OSError: [Errno 107] Transport endpoint is not connected\n",
            "Traceback (most recent call last):\n",
            "  File \"/usr/local/lib/python3.10/dist-packages/IPython/core/interactiveshell.py\", line 3553, in run_code\n",
            "    exec(code_obj, self.user_global_ns, self.user_ns)\n",
            "  File \"<ipython-input-10-5cd72ee79aa1>\", line 2, in <cell line: 2>\n",
            "    os.chdir(\"drive/My Drive/Project/DadosPreprocessados\")\n",
            "OSError: [Errno 107] Transport endpoint is not connected: 'drive/My Drive/Project/DadosPreprocessados'\n",
            "\n",
            "During handling of the above exception, another exception occurred:\n",
            "\n",
            "Traceback (most recent call last):\n",
            "  File \"/usr/local/lib/python3.10/dist-packages/IPython/core/interactiveshell.py\", line 2099, in showtraceback\n",
            "    stb = value._render_traceback_()\n",
            "AttributeError: 'OSError' object has no attribute '_render_traceback_'\n",
            "\n",
            "During handling of the above exception, another exception occurred:\n",
            "\n",
            "Traceback (most recent call last):\n",
            "  File \"/usr/local/lib/python3.10/dist-packages/IPython/core/interactiveshell.py\", line 3473, in run_ast_nodes\n",
            "    if (await self.run_code(code, result,  async_=asy)):\n",
            "  File \"/usr/local/lib/python3.10/dist-packages/IPython/core/interactiveshell.py\", line 3575, in run_code\n",
            "    self.showtraceback(running_compiled_code=True)\n",
            "  File \"/usr/local/lib/python3.10/dist-packages/IPython/core/interactiveshell.py\", line 2101, in showtraceback\n",
            "    stb = self.InteractiveTB.structured_traceback(etype,\n",
            "  File \"/usr/local/lib/python3.10/dist-packages/IPython/core/ultratb.py\", line 1367, in structured_traceback\n",
            "    return FormattedTB.structured_traceback(\n",
            "  File \"/usr/local/lib/python3.10/dist-packages/IPython/core/ultratb.py\", line 1267, in structured_traceback\n",
            "    return VerboseTB.structured_traceback(\n",
            "  File \"/usr/local/lib/python3.10/dist-packages/IPython/core/ultratb.py\", line 1124, in structured_traceback\n",
            "    formatted_exception = self.format_exception_as_a_whole(etype, evalue, etb, number_of_lines_of_context,\n",
            "  File \"/usr/local/lib/python3.10/dist-packages/IPython/core/ultratb.py\", line 1082, in format_exception_as_a_whole\n",
            "    last_unique, recursion_repeat = find_recursion(orig_etype, evalue, records)\n",
            "  File \"/usr/local/lib/python3.10/dist-packages/IPython/core/ultratb.py\", line 382, in find_recursion\n",
            "    return len(records), 0\n",
            "TypeError: object of type 'NoneType' has no len()\n",
            "\n",
            "During handling of the above exception, another exception occurred:\n",
            "\n",
            "Traceback (most recent call last):\n",
            "  File \"/usr/local/lib/python3.10/dist-packages/IPython/core/interactiveshell.py\", line 2099, in showtraceback\n",
            "    stb = value._render_traceback_()\n",
            "AttributeError: 'TypeError' object has no attribute '_render_traceback_'\n",
            "\n",
            "During handling of the above exception, another exception occurred:\n",
            "\n",
            "Traceback (most recent call last):\n",
            "  File \"/usr/local/lib/python3.10/dist-packages/IPython/core/interactiveshell.py\", line 3030, in _run_cell\n",
            "    return runner(coro)\n",
            "  File \"/usr/local/lib/python3.10/dist-packages/IPython/core/async_helpers.py\", line 78, in _pseudo_sync_runner\n",
            "    coro.send(None)\n",
            "  File \"/usr/local/lib/python3.10/dist-packages/IPython/core/interactiveshell.py\", line 3257, in run_cell_async\n",
            "    has_raised = await self.run_ast_nodes(code_ast.body, cell_name,\n",
            "  File \"/usr/local/lib/python3.10/dist-packages/IPython/core/interactiveshell.py\", line 3492, in run_ast_nodes\n",
            "    self.showtraceback()\n",
            "  File \"/usr/local/lib/python3.10/dist-packages/IPython/core/interactiveshell.py\", line 2101, in showtraceback\n",
            "    stb = self.InteractiveTB.structured_traceback(etype,\n",
            "  File \"/usr/local/lib/python3.10/dist-packages/IPython/core/ultratb.py\", line 1367, in structured_traceback\n",
            "    return FormattedTB.structured_traceback(\n",
            "  File \"/usr/local/lib/python3.10/dist-packages/IPython/core/ultratb.py\", line 1267, in structured_traceback\n",
            "    return VerboseTB.structured_traceback(\n",
            "  File \"/usr/local/lib/python3.10/dist-packages/IPython/core/ultratb.py\", line 1142, in structured_traceback\n",
            "    formatted_exceptions += self.format_exception_as_a_whole(etype, evalue, etb, lines_of_context,\n",
            "  File \"/usr/local/lib/python3.10/dist-packages/IPython/core/ultratb.py\", line 1082, in format_exception_as_a_whole\n",
            "    last_unique, recursion_repeat = find_recursion(orig_etype, evalue, records)\n",
            "  File \"/usr/local/lib/python3.10/dist-packages/IPython/core/ultratb.py\", line 382, in find_recursion\n",
            "    return len(records), 0\n",
            "TypeError: object of type 'NoneType' has no len()\n",
            "\n",
            "During handling of the above exception, another exception occurred:\n",
            "\n",
            "Traceback (most recent call last):\n",
            "  File \"/usr/local/lib/python3.10/dist-packages/IPython/core/interactiveshell.py\", line 2099, in showtraceback\n",
            "    stb = value._render_traceback_()\n",
            "AttributeError: 'TypeError' object has no attribute '_render_traceback_'\n",
            "\n",
            "During handling of the above exception, another exception occurred:\n",
            "\n",
            "Traceback (most recent call last):\n",
            "  File \"/usr/local/lib/python3.10/dist-packages/IPython/core/ultratb.py\", line 1101, in get_records\n",
            "    return _fixed_getinnerframes(etb, number_of_lines_of_context, tb_offset)\n",
            "  File \"/usr/local/lib/python3.10/dist-packages/IPython/core/ultratb.py\", line 248, in wrapped\n",
            "    return f(*args, **kwargs)\n",
            "  File \"/usr/local/lib/python3.10/dist-packages/IPython/core/ultratb.py\", line 281, in _fixed_getinnerframes\n",
            "    records = fix_frame_records_filenames(inspect.getinnerframes(etb, context))\n",
            "  File \"/usr/lib/python3.10/inspect.py\", line 1662, in getinnerframes\n",
            "    frameinfo = (tb.tb_frame,) + getframeinfo(tb, context)\n",
            "  File \"/usr/lib/python3.10/inspect.py\", line 1620, in getframeinfo\n",
            "    filename = getsourcefile(frame) or getfile(frame)\n",
            "  File \"/usr/lib/python3.10/inspect.py\", line 829, in getsourcefile\n",
            "    module = getmodule(object, filename)\n",
            "  File \"/usr/lib/python3.10/inspect.py\", line 861, in getmodule\n",
            "    file = getabsfile(object, _filename)\n",
            "  File \"/usr/lib/python3.10/inspect.py\", line 845, in getabsfile\n",
            "    return os.path.normcase(os.path.abspath(_filename))\n",
            "  File \"/usr/lib/python3.10/posixpath.py\", line 384, in abspath\n",
            "    cwd = os.getcwd()\n",
            "OSError: [Errno 107] Transport endpoint is not connected\n"
          ]
        }
      ],
      "source": [
        "import os\n",
        "os.chdir(\"drive/My Drive/Project/DadosPreprocessados\")"
      ],
      "id": "N_Nkc0z42C3l"
    },
    {
      "cell_type": "code",
      "execution_count": null,
      "metadata": {
        "colab": {
          "background_save": true,
          "base_uri": "https://localhost:8080/",
          "height": 222
        },
        "id": "fd0da986-f602-4c8e-97c7-efe1f7ce250d",
        "outputId": "70182678-5c0a-43db-963e-3db86b30d7f2"
      },
      "outputs": [
        {
          "name": "stderr",
          "output_type": "stream",
          "text": [
            "ERROR:root:Internal Python error in the inspect module.\n",
            "Below is the traceback from this internal error.\n",
            "\n",
            "ERROR:root:Internal Python error in the inspect module.\n",
            "Below is the traceback from this internal error.\n",
            "\n",
            "ERROR:root:Internal Python error in the inspect module.\n",
            "Below is the traceback from this internal error.\n",
            "\n"
          ]
        },
        {
          "name": "stdout",
          "output_type": "stream",
          "text": [
            "Traceback (most recent call last):\n",
            "  File \"/usr/local/lib/python3.10/dist-packages/IPython/core/interactiveshell.py\", line 3553, in run_code\n",
            "    exec(code_obj, self.user_global_ns, self.user_ns)\n",
            "  File \"<ipython-input-10-47c3e0d38a86>\", line 1, in <cell line: 1>\n",
            "    df_datasources = pd.read_csv(\"datasources_p.csv\")\n",
            "NameError: name 'pd' is not defined\n",
            "\n",
            "During handling of the above exception, another exception occurred:\n",
            "\n",
            "Traceback (most recent call last):\n",
            "  File \"/usr/local/lib/python3.10/dist-packages/IPython/core/interactiveshell.py\", line 2099, in showtraceback\n",
            "    stb = value._render_traceback_()\n",
            "AttributeError: 'NameError' object has no attribute '_render_traceback_'\n",
            "\n",
            "During handling of the above exception, another exception occurred:\n",
            "\n",
            "Traceback (most recent call last):\n",
            "  File \"/usr/local/lib/python3.10/dist-packages/IPython/core/ultratb.py\", line 1101, in get_records\n",
            "    return _fixed_getinnerframes(etb, number_of_lines_of_context, tb_offset)\n",
            "  File \"/usr/local/lib/python3.10/dist-packages/IPython/core/ultratb.py\", line 248, in wrapped\n",
            "    return f(*args, **kwargs)\n",
            "  File \"/usr/local/lib/python3.10/dist-packages/IPython/core/ultratb.py\", line 281, in _fixed_getinnerframes\n",
            "    records = fix_frame_records_filenames(inspect.getinnerframes(etb, context))\n",
            "  File \"/usr/lib/python3.10/inspect.py\", line 1662, in getinnerframes\n",
            "    frameinfo = (tb.tb_frame,) + getframeinfo(tb, context)\n",
            "  File \"/usr/lib/python3.10/inspect.py\", line 1620, in getframeinfo\n",
            "    filename = getsourcefile(frame) or getfile(frame)\n",
            "  File \"/usr/lib/python3.10/inspect.py\", line 829, in getsourcefile\n",
            "    module = getmodule(object, filename)\n",
            "  File \"/usr/lib/python3.10/inspect.py\", line 861, in getmodule\n",
            "    file = getabsfile(object, _filename)\n",
            "  File \"/usr/lib/python3.10/inspect.py\", line 845, in getabsfile\n",
            "    return os.path.normcase(os.path.abspath(_filename))\n",
            "  File \"/usr/lib/python3.10/posixpath.py\", line 384, in abspath\n",
            "    cwd = os.getcwd()\n",
            "OSError: [Errno 107] Transport endpoint is not connected\n",
            "Traceback (most recent call last):\n",
            "  File \"/usr/local/lib/python3.10/dist-packages/IPython/core/interactiveshell.py\", line 3553, in run_code\n",
            "    exec(code_obj, self.user_global_ns, self.user_ns)\n",
            "  File \"<ipython-input-10-47c3e0d38a86>\", line 1, in <cell line: 1>\n",
            "    df_datasources = pd.read_csv(\"datasources_p.csv\")\n",
            "NameError: name 'pd' is not defined\n",
            "\n",
            "During handling of the above exception, another exception occurred:\n",
            "\n",
            "Traceback (most recent call last):\n",
            "  File \"/usr/local/lib/python3.10/dist-packages/IPython/core/interactiveshell.py\", line 2099, in showtraceback\n",
            "    stb = value._render_traceback_()\n",
            "AttributeError: 'NameError' object has no attribute '_render_traceback_'\n",
            "\n",
            "During handling of the above exception, another exception occurred:\n",
            "\n",
            "Traceback (most recent call last):\n",
            "  File \"/usr/local/lib/python3.10/dist-packages/IPython/core/interactiveshell.py\", line 3473, in run_ast_nodes\n",
            "    if (await self.run_code(code, result,  async_=asy)):\n",
            "  File \"/usr/local/lib/python3.10/dist-packages/IPython/core/interactiveshell.py\", line 3575, in run_code\n",
            "    self.showtraceback(running_compiled_code=True)\n",
            "  File \"/usr/local/lib/python3.10/dist-packages/IPython/core/interactiveshell.py\", line 2101, in showtraceback\n",
            "    stb = self.InteractiveTB.structured_traceback(etype,\n",
            "  File \"/usr/local/lib/python3.10/dist-packages/IPython/core/ultratb.py\", line 1367, in structured_traceback\n",
            "    return FormattedTB.structured_traceback(\n",
            "  File \"/usr/local/lib/python3.10/dist-packages/IPython/core/ultratb.py\", line 1267, in structured_traceback\n",
            "    return VerboseTB.structured_traceback(\n",
            "  File \"/usr/local/lib/python3.10/dist-packages/IPython/core/ultratb.py\", line 1124, in structured_traceback\n",
            "    formatted_exception = self.format_exception_as_a_whole(etype, evalue, etb, number_of_lines_of_context,\n",
            "  File \"/usr/local/lib/python3.10/dist-packages/IPython/core/ultratb.py\", line 1082, in format_exception_as_a_whole\n",
            "    last_unique, recursion_repeat = find_recursion(orig_etype, evalue, records)\n",
            "  File \"/usr/local/lib/python3.10/dist-packages/IPython/core/ultratb.py\", line 382, in find_recursion\n",
            "    return len(records), 0\n",
            "TypeError: object of type 'NoneType' has no len()\n",
            "\n",
            "During handling of the above exception, another exception occurred:\n",
            "\n",
            "Traceback (most recent call last):\n",
            "  File \"/usr/local/lib/python3.10/dist-packages/IPython/core/interactiveshell.py\", line 2099, in showtraceback\n",
            "    stb = value._render_traceback_()\n",
            "AttributeError: 'TypeError' object has no attribute '_render_traceback_'\n",
            "\n",
            "During handling of the above exception, another exception occurred:\n",
            "\n",
            "Traceback (most recent call last):\n",
            "  File \"/usr/local/lib/python3.10/dist-packages/IPython/core/ultratb.py\", line 1101, in get_records\n",
            "    return _fixed_getinnerframes(etb, number_of_lines_of_context, tb_offset)\n",
            "  File \"/usr/local/lib/python3.10/dist-packages/IPython/core/ultratb.py\", line 248, in wrapped\n",
            "    return f(*args, **kwargs)\n",
            "  File \"/usr/local/lib/python3.10/dist-packages/IPython/core/ultratb.py\", line 281, in _fixed_getinnerframes\n",
            "    records = fix_frame_records_filenames(inspect.getinnerframes(etb, context))\n",
            "  File \"/usr/lib/python3.10/inspect.py\", line 1662, in getinnerframes\n",
            "    frameinfo = (tb.tb_frame,) + getframeinfo(tb, context)\n",
            "  File \"/usr/lib/python3.10/inspect.py\", line 1620, in getframeinfo\n",
            "    filename = getsourcefile(frame) or getfile(frame)\n",
            "  File \"/usr/lib/python3.10/inspect.py\", line 829, in getsourcefile\n",
            "    module = getmodule(object, filename)\n",
            "  File \"/usr/lib/python3.10/inspect.py\", line 861, in getmodule\n",
            "    file = getabsfile(object, _filename)\n",
            "  File \"/usr/lib/python3.10/inspect.py\", line 845, in getabsfile\n",
            "    return os.path.normcase(os.path.abspath(_filename))\n",
            "  File \"/usr/lib/python3.10/posixpath.py\", line 384, in abspath\n",
            "    cwd = os.getcwd()\n",
            "OSError: [Errno 107] Transport endpoint is not connected\n",
            "Traceback (most recent call last):\n",
            "  File \"/usr/local/lib/python3.10/dist-packages/IPython/core/interactiveshell.py\", line 3553, in run_code\n",
            "    exec(code_obj, self.user_global_ns, self.user_ns)\n",
            "  File \"<ipython-input-10-47c3e0d38a86>\", line 1, in <cell line: 1>\n",
            "    df_datasources = pd.read_csv(\"datasources_p.csv\")\n",
            "NameError: name 'pd' is not defined\n",
            "\n",
            "During handling of the above exception, another exception occurred:\n",
            "\n",
            "Traceback (most recent call last):\n",
            "  File \"/usr/local/lib/python3.10/dist-packages/IPython/core/interactiveshell.py\", line 2099, in showtraceback\n",
            "    stb = value._render_traceback_()\n",
            "AttributeError: 'NameError' object has no attribute '_render_traceback_'\n",
            "\n",
            "During handling of the above exception, another exception occurred:\n",
            "\n",
            "Traceback (most recent call last):\n",
            "  File \"/usr/local/lib/python3.10/dist-packages/IPython/core/interactiveshell.py\", line 3473, in run_ast_nodes\n",
            "    if (await self.run_code(code, result,  async_=asy)):\n",
            "  File \"/usr/local/lib/python3.10/dist-packages/IPython/core/interactiveshell.py\", line 3575, in run_code\n",
            "    self.showtraceback(running_compiled_code=True)\n",
            "  File \"/usr/local/lib/python3.10/dist-packages/IPython/core/interactiveshell.py\", line 2101, in showtraceback\n",
            "    stb = self.InteractiveTB.structured_traceback(etype,\n",
            "  File \"/usr/local/lib/python3.10/dist-packages/IPython/core/ultratb.py\", line 1367, in structured_traceback\n",
            "    return FormattedTB.structured_traceback(\n",
            "  File \"/usr/local/lib/python3.10/dist-packages/IPython/core/ultratb.py\", line 1267, in structured_traceback\n",
            "    return VerboseTB.structured_traceback(\n",
            "  File \"/usr/local/lib/python3.10/dist-packages/IPython/core/ultratb.py\", line 1124, in structured_traceback\n",
            "    formatted_exception = self.format_exception_as_a_whole(etype, evalue, etb, number_of_lines_of_context,\n",
            "  File \"/usr/local/lib/python3.10/dist-packages/IPython/core/ultratb.py\", line 1082, in format_exception_as_a_whole\n",
            "    last_unique, recursion_repeat = find_recursion(orig_etype, evalue, records)\n",
            "  File \"/usr/local/lib/python3.10/dist-packages/IPython/core/ultratb.py\", line 382, in find_recursion\n",
            "    return len(records), 0\n",
            "TypeError: object of type 'NoneType' has no len()\n",
            "\n",
            "During handling of the above exception, another exception occurred:\n",
            "\n",
            "Traceback (most recent call last):\n",
            "  File \"/usr/local/lib/python3.10/dist-packages/IPython/core/interactiveshell.py\", line 2099, in showtraceback\n",
            "    stb = value._render_traceback_()\n",
            "AttributeError: 'TypeError' object has no attribute '_render_traceback_'\n",
            "\n",
            "During handling of the above exception, another exception occurred:\n",
            "\n",
            "Traceback (most recent call last):\n",
            "  File \"/usr/local/lib/python3.10/dist-packages/IPython/core/interactiveshell.py\", line 3030, in _run_cell\n",
            "    return runner(coro)\n",
            "  File \"/usr/local/lib/python3.10/dist-packages/IPython/core/async_helpers.py\", line 78, in _pseudo_sync_runner\n",
            "    coro.send(None)\n",
            "  File \"/usr/local/lib/python3.10/dist-packages/IPython/core/interactiveshell.py\", line 3257, in run_cell_async\n",
            "    has_raised = await self.run_ast_nodes(code_ast.body, cell_name,\n",
            "  File \"/usr/local/lib/python3.10/dist-packages/IPython/core/interactiveshell.py\", line 3492, in run_ast_nodes\n",
            "    self.showtraceback()\n",
            "  File \"/usr/local/lib/python3.10/dist-packages/IPython/core/interactiveshell.py\", line 2101, in showtraceback\n",
            "    stb = self.InteractiveTB.structured_traceback(etype,\n",
            "  File \"/usr/local/lib/python3.10/dist-packages/IPython/core/ultratb.py\", line 1367, in structured_traceback\n",
            "    return FormattedTB.structured_traceback(\n",
            "  File \"/usr/local/lib/python3.10/dist-packages/IPython/core/ultratb.py\", line 1267, in structured_traceback\n",
            "    return VerboseTB.structured_traceback(\n",
            "  File \"/usr/local/lib/python3.10/dist-packages/IPython/core/ultratb.py\", line 1142, in structured_traceback\n",
            "    formatted_exceptions += self.format_exception_as_a_whole(etype, evalue, etb, lines_of_context,\n",
            "  File \"/usr/local/lib/python3.10/dist-packages/IPython/core/ultratb.py\", line 1082, in format_exception_as_a_whole\n",
            "    last_unique, recursion_repeat = find_recursion(orig_etype, evalue, records)\n",
            "  File \"/usr/local/lib/python3.10/dist-packages/IPython/core/ultratb.py\", line 382, in find_recursion\n",
            "    return len(records), 0\n",
            "TypeError: object of type 'NoneType' has no len()\n",
            "\n",
            "During handling of the above exception, another exception occurred:\n",
            "\n",
            "Traceback (most recent call last):\n",
            "  File \"/usr/local/lib/python3.10/dist-packages/IPython/core/interactiveshell.py\", line 2099, in showtraceback\n",
            "    stb = value._render_traceback_()\n",
            "AttributeError: 'TypeError' object has no attribute '_render_traceback_'\n",
            "\n",
            "During handling of the above exception, another exception occurred:\n",
            "\n",
            "Traceback (most recent call last):\n",
            "  File \"/usr/local/lib/python3.10/dist-packages/IPython/core/ultratb.py\", line 1101, in get_records\n",
            "    return _fixed_getinnerframes(etb, number_of_lines_of_context, tb_offset)\n",
            "  File \"/usr/local/lib/python3.10/dist-packages/IPython/core/ultratb.py\", line 248, in wrapped\n",
            "    return f(*args, **kwargs)\n",
            "  File \"/usr/local/lib/python3.10/dist-packages/IPython/core/ultratb.py\", line 281, in _fixed_getinnerframes\n",
            "    records = fix_frame_records_filenames(inspect.getinnerframes(etb, context))\n",
            "  File \"/usr/lib/python3.10/inspect.py\", line 1662, in getinnerframes\n",
            "    frameinfo = (tb.tb_frame,) + getframeinfo(tb, context)\n",
            "  File \"/usr/lib/python3.10/inspect.py\", line 1620, in getframeinfo\n",
            "    filename = getsourcefile(frame) or getfile(frame)\n",
            "  File \"/usr/lib/python3.10/inspect.py\", line 829, in getsourcefile\n",
            "    module = getmodule(object, filename)\n",
            "  File \"/usr/lib/python3.10/inspect.py\", line 861, in getmodule\n",
            "    file = getabsfile(object, _filename)\n",
            "  File \"/usr/lib/python3.10/inspect.py\", line 845, in getabsfile\n",
            "    return os.path.normcase(os.path.abspath(_filename))\n",
            "  File \"/usr/lib/python3.10/posixpath.py\", line 384, in abspath\n",
            "    cwd = os.getcwd()\n",
            "OSError: [Errno 107] Transport endpoint is not connected\n"
          ]
        }
      ],
      "source": [
        "df_datasources = pd.read_csv(\"datasources_p.csv\")\n",
        "df_series = pd.read_csv(\"series_p.csv\")\n",
        "df_seriesdata = pd.read_csv(\"seriesdata_p.csv\")\n",
        "df_sourcesandseries = pd.read_csv(\"SourcesAndSeries.csv\")"
      ],
      "id": "fd0da986-f602-4c8e-97c7-efe1f7ce250d"
    },
    {
      "cell_type": "code",
      "execution_count": null,
      "metadata": {
        "colab": {
          "background_save": true,
          "base_uri": "https://localhost:8080/",
          "height": 169
        },
        "id": "b0614e5b-8d87-4efe-9580-01a0f25054a4",
        "outputId": "8f1076c4-203a-4122-bcfe-5fc9c0ccc4fc"
      },
      "outputs": [
        {
          "name": "stderr",
          "output_type": "stream",
          "text": [
            "ERROR:root:Internal Python error in the inspect module.\n",
            "Below is the traceback from this internal error.\n",
            "\n"
          ]
        },
        {
          "name": "stdout",
          "output_type": "stream",
          "text": [
            "Traceback (most recent call last):\n",
            "  File \"/usr/local/lib/python3.10/dist-packages/IPython/core/interactiveshell.py\", line 3553, in run_code\n",
            "    exec(code_obj, self.user_global_ns, self.user_ns)\n",
            "  File \"<ipython-input-10-c1835c410937>\", line 1, in <cell line: 1>\n",
            "    df_seriesdata.drop_duplicates()\n",
            "NameError: name 'df_seriesdata' is not defined\n",
            "\n",
            "During handling of the above exception, another exception occurred:\n",
            "\n",
            "Traceback (most recent call last):\n",
            "  File \"/usr/local/lib/python3.10/dist-packages/IPython/core/interactiveshell.py\", line 2099, in showtraceback\n",
            "    stb = value._render_traceback_()\n",
            "AttributeError: 'NameError' object has no attribute '_render_traceback_'\n",
            "\n",
            "During handling of the above exception, another exception occurred:\n",
            "\n",
            "Traceback (most recent call last):\n",
            "  File \"/usr/local/lib/python3.10/dist-packages/IPython/core/ultratb.py\", line 1101, in get_records\n",
            "    return _fixed_getinnerframes(etb, number_of_lines_of_context, tb_offset)\n",
            "  File \"/usr/local/lib/python3.10/dist-packages/IPython/core/ultratb.py\", line 248, in wrapped\n",
            "    return f(*args, **kwargs)\n",
            "  File \"/usr/local/lib/python3.10/dist-packages/IPython/core/ultratb.py\", line 281, in _fixed_getinnerframes\n",
            "    records = fix_frame_records_filenames(inspect.getinnerframes(etb, context))\n",
            "  File \"/usr/lib/python3.10/inspect.py\", line 1662, in getinnerframes\n",
            "    frameinfo = (tb.tb_frame,) + getframeinfo(tb, context)\n",
            "  File \"/usr/lib/python3.10/inspect.py\", line 1620, in getframeinfo\n",
            "    filename = getsourcefile(frame) or getfile(frame)\n",
            "  File \"/usr/lib/python3.10/inspect.py\", line 829, in getsourcefile\n",
            "    module = getmodule(object, filename)\n",
            "  File \"/usr/lib/python3.10/inspect.py\", line 861, in getmodule\n",
            "    file = getabsfile(object, _filename)\n",
            "  File \"/usr/lib/python3.10/inspect.py\", line 845, in getabsfile\n",
            "    return os.path.normcase(os.path.abspath(_filename))\n",
            "  File \"/usr/lib/python3.10/posixpath.py\", line 384, in abspath\n",
            "    cwd = os.getcwd()\n",
            "OSError: [Errno 107] Transport endpoint is not connected\n"
          ]
        },
        {
          "name": "stderr",
          "output_type": "stream",
          "text": [
            "ERROR:root:Internal Python error in the inspect module.\n",
            "Below is the traceback from this internal error.\n",
            "\n"
          ]
        },
        {
          "name": "stdout",
          "output_type": "stream",
          "text": [
            "Traceback (most recent call last):\n",
            "  File \"/usr/local/lib/python3.10/dist-packages/IPython/core/interactiveshell.py\", line 3553, in run_code\n",
            "    exec(code_obj, self.user_global_ns, self.user_ns)\n",
            "  File \"<ipython-input-10-c1835c410937>\", line 1, in <cell line: 1>\n",
            "    df_seriesdata.drop_duplicates()\n",
            "NameError: name 'df_seriesdata' is not defined\n",
            "\n",
            "During handling of the above exception, another exception occurred:\n",
            "\n",
            "Traceback (most recent call last):\n",
            "  File \"/usr/local/lib/python3.10/dist-packages/IPython/core/interactiveshell.py\", line 2099, in showtraceback\n",
            "    stb = value._render_traceback_()\n",
            "AttributeError: 'NameError' object has no attribute '_render_traceback_'\n",
            "\n",
            "During handling of the above exception, another exception occurred:\n",
            "\n",
            "Traceback (most recent call last):\n",
            "  File \"/usr/local/lib/python3.10/dist-packages/IPython/core/interactiveshell.py\", line 3473, in run_ast_nodes\n",
            "    if (await self.run_code(code, result,  async_=asy)):\n",
            "  File \"/usr/local/lib/python3.10/dist-packages/IPython/core/interactiveshell.py\", line 3575, in run_code\n",
            "    self.showtraceback(running_compiled_code=True)\n",
            "  File \"/usr/local/lib/python3.10/dist-packages/IPython/core/interactiveshell.py\", line 2101, in showtraceback\n",
            "    stb = self.InteractiveTB.structured_traceback(etype,\n",
            "  File \"/usr/local/lib/python3.10/dist-packages/IPython/core/ultratb.py\", line 1367, in structured_traceback\n",
            "    return FormattedTB.structured_traceback(\n",
            "  File \"/usr/local/lib/python3.10/dist-packages/IPython/core/ultratb.py\", line 1267, in structured_traceback\n",
            "    return VerboseTB.structured_traceback(\n",
            "  File \"/usr/local/lib/python3.10/dist-packages/IPython/core/ultratb.py\", line 1124, in structured_traceback\n",
            "    formatted_exception = self.format_exception_as_a_whole(etype, evalue, etb, number_of_lines_of_context,\n",
            "  File \"/usr/local/lib/python3.10/dist-packages/IPython/core/ultratb.py\", line 1082, in format_exception_as_a_whole\n",
            "    last_unique, recursion_repeat = find_recursion(orig_etype, evalue, records)\n",
            "  File \"/usr/local/lib/python3.10/dist-packages/IPython/core/ultratb.py\", line 382, in find_recursion\n",
            "    return len(records), 0\n",
            "TypeError: object of type 'NoneType' has no len()\n",
            "\n",
            "During handling of the above exception, another exception occurred:\n",
            "\n",
            "Traceback (most recent call last):\n",
            "  File \"/usr/local/lib/python3.10/dist-packages/IPython/core/interactiveshell.py\", line 2099, in showtraceback\n",
            "    stb = value._render_traceback_()\n",
            "AttributeError: 'TypeError' object has no attribute '_render_traceback_'\n",
            "\n",
            "During handling of the above exception, another exception occurred:\n",
            "\n",
            "Traceback (most recent call last):\n",
            "  File \"/usr/local/lib/python3.10/dist-packages/IPython/core/ultratb.py\", line 1101, in get_records\n",
            "    return _fixed_getinnerframes(etb, number_of_lines_of_context, tb_offset)\n",
            "  File \"/usr/local/lib/python3.10/dist-packages/IPython/core/ultratb.py\", line 248, in wrapped\n",
            "    return f(*args, **kwargs)\n",
            "  File \"/usr/local/lib/python3.10/dist-packages/IPython/core/ultratb.py\", line 281, in _fixed_getinnerframes\n",
            "    records = fix_frame_records_filenames(inspect.getinnerframes(etb, context))\n",
            "  File \"/usr/lib/python3.10/inspect.py\", line 1662, in getinnerframes\n",
            "    frameinfo = (tb.tb_frame,) + getframeinfo(tb, context)\n",
            "  File \"/usr/lib/python3.10/inspect.py\", line 1620, in getframeinfo\n",
            "    filename = getsourcefile(frame) or getfile(frame)\n",
            "  File \"/usr/lib/python3.10/inspect.py\", line 829, in getsourcefile\n",
            "    module = getmodule(object, filename)\n",
            "  File \"/usr/lib/python3.10/inspect.py\", line 861, in getmodule\n",
            "    file = getabsfile(object, _filename)\n",
            "  File \"/usr/lib/python3.10/inspect.py\", line 845, in getabsfile\n",
            "    return os.path.normcase(os.path.abspath(_filename))\n",
            "  File \"/usr/lib/python3.10/posixpath.py\", line 384, in abspath\n",
            "    cwd = os.getcwd()\n",
            "OSError: [Errno 107] Transport endpoint is not connected\n"
          ]
        },
        {
          "name": "stderr",
          "output_type": "stream",
          "text": [
            "ERROR:root:Internal Python error in the inspect module.\n",
            "Below is the traceback from this internal error.\n",
            "\n"
          ]
        },
        {
          "name": "stdout",
          "output_type": "stream",
          "text": [
            "Traceback (most recent call last):\n",
            "  File \"/usr/local/lib/python3.10/dist-packages/IPython/core/interactiveshell.py\", line 3553, in run_code\n",
            "    exec(code_obj, self.user_global_ns, self.user_ns)\n",
            "  File \"<ipython-input-10-c1835c410937>\", line 1, in <cell line: 1>\n",
            "    df_seriesdata.drop_duplicates()\n",
            "NameError: name 'df_seriesdata' is not defined\n",
            "\n",
            "During handling of the above exception, another exception occurred:\n",
            "\n",
            "Traceback (most recent call last):\n",
            "  File \"/usr/local/lib/python3.10/dist-packages/IPython/core/interactiveshell.py\", line 2099, in showtraceback\n",
            "    stb = value._render_traceback_()\n",
            "AttributeError: 'NameError' object has no attribute '_render_traceback_'\n",
            "\n",
            "During handling of the above exception, another exception occurred:\n",
            "\n",
            "Traceback (most recent call last):\n",
            "  File \"/usr/local/lib/python3.10/dist-packages/IPython/core/interactiveshell.py\", line 3473, in run_ast_nodes\n",
            "    if (await self.run_code(code, result,  async_=asy)):\n",
            "  File \"/usr/local/lib/python3.10/dist-packages/IPython/core/interactiveshell.py\", line 3575, in run_code\n",
            "    self.showtraceback(running_compiled_code=True)\n",
            "  File \"/usr/local/lib/python3.10/dist-packages/IPython/core/interactiveshell.py\", line 2101, in showtraceback\n",
            "    stb = self.InteractiveTB.structured_traceback(etype,\n",
            "  File \"/usr/local/lib/python3.10/dist-packages/IPython/core/ultratb.py\", line 1367, in structured_traceback\n",
            "    return FormattedTB.structured_traceback(\n",
            "  File \"/usr/local/lib/python3.10/dist-packages/IPython/core/ultratb.py\", line 1267, in structured_traceback\n",
            "    return VerboseTB.structured_traceback(\n",
            "  File \"/usr/local/lib/python3.10/dist-packages/IPython/core/ultratb.py\", line 1124, in structured_traceback\n",
            "    formatted_exception = self.format_exception_as_a_whole(etype, evalue, etb, number_of_lines_of_context,\n",
            "  File \"/usr/local/lib/python3.10/dist-packages/IPython/core/ultratb.py\", line 1082, in format_exception_as_a_whole\n",
            "    last_unique, recursion_repeat = find_recursion(orig_etype, evalue, records)\n",
            "  File \"/usr/local/lib/python3.10/dist-packages/IPython/core/ultratb.py\", line 382, in find_recursion\n",
            "    return len(records), 0\n",
            "TypeError: object of type 'NoneType' has no len()\n",
            "\n",
            "During handling of the above exception, another exception occurred:\n",
            "\n",
            "Traceback (most recent call last):\n",
            "  File \"/usr/local/lib/python3.10/dist-packages/IPython/core/interactiveshell.py\", line 2099, in showtraceback\n",
            "    stb = value._render_traceback_()\n",
            "AttributeError: 'TypeError' object has no attribute '_render_traceback_'\n",
            "\n",
            "During handling of the above exception, another exception occurred:\n",
            "\n",
            "Traceback (most recent call last):\n",
            "  File \"/usr/local/lib/python3.10/dist-packages/IPython/core/interactiveshell.py\", line 3030, in _run_cell\n",
            "    return runner(coro)\n",
            "  File \"/usr/local/lib/python3.10/dist-packages/IPython/core/async_helpers.py\", line 78, in _pseudo_sync_runner\n",
            "    coro.send(None)\n",
            "  File \"/usr/local/lib/python3.10/dist-packages/IPython/core/interactiveshell.py\", line 3257, in run_cell_async\n",
            "    has_raised = await self.run_ast_nodes(code_ast.body, cell_name,\n",
            "  File \"/usr/local/lib/python3.10/dist-packages/IPython/core/interactiveshell.py\", line 3492, in run_ast_nodes\n",
            "    self.showtraceback()\n",
            "  File \"/usr/local/lib/python3.10/dist-packages/IPython/core/interactiveshell.py\", line 2101, in showtraceback\n",
            "    stb = self.InteractiveTB.structured_traceback(etype,\n",
            "  File \"/usr/local/lib/python3.10/dist-packages/IPython/core/ultratb.py\", line 1367, in structured_traceback\n",
            "    return FormattedTB.structured_traceback(\n",
            "  File \"/usr/local/lib/python3.10/dist-packages/IPython/core/ultratb.py\", line 1267, in structured_traceback\n",
            "    return VerboseTB.structured_traceback(\n",
            "  File \"/usr/local/lib/python3.10/dist-packages/IPython/core/ultratb.py\", line 1142, in structured_traceback\n",
            "    formatted_exceptions += self.format_exception_as_a_whole(etype, evalue, etb, lines_of_context,\n",
            "  File \"/usr/local/lib/python3.10/dist-packages/IPython/core/ultratb.py\", line 1082, in format_exception_as_a_whole\n",
            "    last_unique, recursion_repeat = find_recursion(orig_etype, evalue, records)\n",
            "  File \"/usr/local/lib/python3.10/dist-packages/IPython/core/ultratb.py\", line 382, in find_recursion\n",
            "    return len(records), 0\n",
            "TypeError: object of type 'NoneType' has no len()\n",
            "\n",
            "During handling of the above exception, another exception occurred:\n",
            "\n",
            "Traceback (most recent call last):\n",
            "  File \"/usr/local/lib/python3.10/dist-packages/IPython/core/interactiveshell.py\", line 2099, in showtraceback\n",
            "    stb = value._render_traceback_()\n",
            "AttributeError: 'TypeError' object has no attribute '_render_traceback_'\n",
            "\n",
            "During handling of the above exception, another exception occurred:\n",
            "\n",
            "Traceback (most recent call last):\n",
            "  File \"/usr/local/lib/python3.10/dist-packages/IPython/core/ultratb.py\", line 1101, in get_records\n",
            "    return _fixed_getinnerframes(etb, number_of_lines_of_context, tb_offset)\n",
            "  File \"/usr/local/lib/python3.10/dist-packages/IPython/core/ultratb.py\", line 248, in wrapped\n",
            "    return f(*args, **kwargs)\n",
            "  File \"/usr/local/lib/python3.10/dist-packages/IPython/core/ultratb.py\", line 281, in _fixed_getinnerframes\n",
            "    records = fix_frame_records_filenames(inspect.getinnerframes(etb, context))\n",
            "  File \"/usr/lib/python3.10/inspect.py\", line 1662, in getinnerframes\n",
            "    frameinfo = (tb.tb_frame,) + getframeinfo(tb, context)\n",
            "  File \"/usr/lib/python3.10/inspect.py\", line 1620, in getframeinfo\n",
            "    filename = getsourcefile(frame) or getfile(frame)\n",
            "  File \"/usr/lib/python3.10/inspect.py\", line 829, in getsourcefile\n",
            "    module = getmodule(object, filename)\n",
            "  File \"/usr/lib/python3.10/inspect.py\", line 861, in getmodule\n",
            "    file = getabsfile(object, _filename)\n",
            "  File \"/usr/lib/python3.10/inspect.py\", line 845, in getabsfile\n",
            "    return os.path.normcase(os.path.abspath(_filename))\n",
            "  File \"/usr/lib/python3.10/posixpath.py\", line 384, in abspath\n",
            "    cwd = os.getcwd()\n",
            "OSError: [Errno 107] Transport endpoint is not connected\n"
          ]
        }
      ],
      "source": [
        "df_seriesdata.drop_duplicates()"
      ],
      "id": "b0614e5b-8d87-4efe-9580-01a0f25054a4"
    },
    {
      "cell_type": "code",
      "execution_count": null,
      "metadata": {
        "colab": {
          "background_save": true
        },
        "id": "cd0e9fb2-37cd-425f-8518-df63650eb179",
        "outputId": "c787716f-8921-4fae-8839-7941fb9680a1"
      },
      "outputs": [
        {
          "name": "stderr",
          "output_type": "stream",
          "text": [
            "ERROR:root:Internal Python error in the inspect module.\n",
            "Below is the traceback from this internal error.\n",
            "\n",
            "ERROR:root:Internal Python error in the inspect module.\n",
            "Below is the traceback from this internal error.\n",
            "\n"
          ]
        },
        {
          "name": "stdout",
          "output_type": "stream",
          "text": [
            "Traceback (most recent call last):\n",
            "  File \"/usr/local/lib/python3.10/dist-packages/IPython/core/interactiveshell.py\", line 3553, in run_code\n",
            "    exec(code_obj, self.user_global_ns, self.user_ns)\n",
            "  File \"<ipython-input-10-1f5aa19bb70b>\", line 1, in <cell line: 1>\n",
            "    df_series['seriesvariable_standardname'] = df_series['seriesvariable_standardname'].str.replace('(',' ', regex = False).str.replace(')', '', regex = False)\n",
            "NameError: name 'df_series' is not defined\n",
            "\n",
            "During handling of the above exception, another exception occurred:\n",
            "\n",
            "Traceback (most recent call last):\n",
            "  File \"/usr/local/lib/python3.10/dist-packages/IPython/core/interactiveshell.py\", line 2099, in showtraceback\n",
            "    stb = value._render_traceback_()\n",
            "AttributeError: 'NameError' object has no attribute '_render_traceback_'\n",
            "\n",
            "During handling of the above exception, another exception occurred:\n",
            "\n",
            "Traceback (most recent call last):\n",
            "  File \"/usr/local/lib/python3.10/dist-packages/IPython/core/ultratb.py\", line 1101, in get_records\n",
            "    return _fixed_getinnerframes(etb, number_of_lines_of_context, tb_offset)\n",
            "  File \"/usr/local/lib/python3.10/dist-packages/IPython/core/ultratb.py\", line 248, in wrapped\n",
            "    return f(*args, **kwargs)\n",
            "  File \"/usr/local/lib/python3.10/dist-packages/IPython/core/ultratb.py\", line 281, in _fixed_getinnerframes\n",
            "    records = fix_frame_records_filenames(inspect.getinnerframes(etb, context))\n",
            "  File \"/usr/lib/python3.10/inspect.py\", line 1662, in getinnerframes\n",
            "    frameinfo = (tb.tb_frame,) + getframeinfo(tb, context)\n",
            "  File \"/usr/lib/python3.10/inspect.py\", line 1620, in getframeinfo\n",
            "    filename = getsourcefile(frame) or getfile(frame)\n",
            "  File \"/usr/lib/python3.10/inspect.py\", line 829, in getsourcefile\n",
            "    module = getmodule(object, filename)\n",
            "  File \"/usr/lib/python3.10/inspect.py\", line 861, in getmodule\n",
            "    file = getabsfile(object, _filename)\n",
            "  File \"/usr/lib/python3.10/inspect.py\", line 845, in getabsfile\n",
            "    return os.path.normcase(os.path.abspath(_filename))\n",
            "  File \"/usr/lib/python3.10/posixpath.py\", line 384, in abspath\n",
            "    cwd = os.getcwd()\n",
            "OSError: [Errno 107] Transport endpoint is not connected\n",
            "Traceback (most recent call last):\n",
            "  File \"/usr/local/lib/python3.10/dist-packages/IPython/core/interactiveshell.py\", line 3553, in run_code\n",
            "    exec(code_obj, self.user_global_ns, self.user_ns)\n",
            "  File \"<ipython-input-10-1f5aa19bb70b>\", line 1, in <cell line: 1>\n",
            "    df_series['seriesvariable_standardname'] = df_series['seriesvariable_standardname'].str.replace('(',' ', regex = False).str.replace(')', '', regex = False)\n",
            "NameError: name 'df_series' is not defined\n",
            "\n",
            "During handling of the above exception, another exception occurred:\n",
            "\n",
            "Traceback (most recent call last):\n",
            "  File \"/usr/local/lib/python3.10/dist-packages/IPython/core/interactiveshell.py\", line 2099, in showtraceback\n",
            "    stb = value._render_traceback_()\n",
            "AttributeError: 'NameError' object has no attribute '_render_traceback_'\n",
            "\n",
            "During handling of the above exception, another exception occurred:\n",
            "\n",
            "Traceback (most recent call last):\n",
            "  File \"/usr/local/lib/python3.10/dist-packages/IPython/core/interactiveshell.py\", line 3473, in run_ast_nodes\n",
            "    if (await self.run_code(code, result,  async_=asy)):\n",
            "  File \"/usr/local/lib/python3.10/dist-packages/IPython/core/interactiveshell.py\", line 3575, in run_code\n",
            "    self.showtraceback(running_compiled_code=True)\n",
            "  File \"/usr/local/lib/python3.10/dist-packages/IPython/core/interactiveshell.py\", line 2101, in showtraceback\n",
            "    stb = self.InteractiveTB.structured_traceback(etype,\n",
            "  File \"/usr/local/lib/python3.10/dist-packages/IPython/core/ultratb.py\", line 1367, in structured_traceback\n",
            "    return FormattedTB.structured_traceback(\n",
            "  File \"/usr/local/lib/python3.10/dist-packages/IPython/core/ultratb.py\", line 1267, in structured_traceback\n",
            "    return VerboseTB.structured_traceback(\n",
            "  File \"/usr/local/lib/python3.10/dist-packages/IPython/core/ultratb.py\", line 1124, in structured_traceback\n",
            "    formatted_exception = self.format_exception_as_a_whole(etype, evalue, etb, number_of_lines_of_context,\n",
            "  File \"/usr/local/lib/python3.10/dist-packages/IPython/core/ultratb.py\", line 1082, in format_exception_as_a_whole\n",
            "    last_unique, recursion_repeat = find_recursion(orig_etype, evalue, records)\n",
            "  File \"/usr/local/lib/python3.10/dist-packages/IPython/core/ultratb.py\", line 382, in find_recursion\n",
            "    return len(records), 0\n",
            "TypeError: object of type 'NoneType' has no len()\n",
            "\n",
            "During handling of the above exception, another exception occurred:\n",
            "\n",
            "Traceback (most recent call last):\n",
            "  File \"/usr/local/lib/python3.10/dist-packages/IPython/core/interactiveshell.py\", line 2099, in showtraceback\n",
            "    stb = value._render_traceback_()\n",
            "AttributeError: 'TypeError' object has no attribute '_render_traceback_'\n",
            "\n",
            "During handling of the above exception, another exception occurred:\n",
            "\n",
            "Traceback (most recent call last):\n",
            "  File \"/usr/local/lib/python3.10/dist-packages/IPython/core/ultratb.py\", line 1101, in get_records\n",
            "    return _fixed_getinnerframes(etb, number_of_lines_of_context, tb_offset)\n",
            "  File \"/usr/local/lib/python3.10/dist-packages/IPython/core/ultratb.py\", line 248, in wrapped\n",
            "    return f(*args, **kwargs)\n",
            "  File \"/usr/local/lib/python3.10/dist-packages/IPython/core/ultratb.py\", line 281, in _fixed_getinnerframes\n",
            "    records = fix_frame_records_filenames(inspect.getinnerframes(etb, context))\n",
            "  File \"/usr/lib/python3.10/inspect.py\", line 1662, in getinnerframes\n",
            "    frameinfo = (tb.tb_frame,) + getframeinfo(tb, context)\n",
            "  File \"/usr/lib/python3.10/inspect.py\", line 1620, in getframeinfo\n",
            "    filename = getsourcefile(frame) or getfile(frame)\n",
            "  File \"/usr/lib/python3.10/inspect.py\", line 829, in getsourcefile\n",
            "    module = getmodule(object, filename)\n",
            "  File \"/usr/lib/python3.10/inspect.py\", line 861, in getmodule\n",
            "    file = getabsfile(object, _filename)\n",
            "  File \"/usr/lib/python3.10/inspect.py\", line 845, in getabsfile\n",
            "    return os.path.normcase(os.path.abspath(_filename))\n",
            "  File \"/usr/lib/python3.10/posixpath.py\", line 384, in abspath\n",
            "    cwd = os.getcwd()\n",
            "OSError: [Errno 107] Transport endpoint is not connected\n"
          ]
        },
        {
          "name": "stderr",
          "output_type": "stream",
          "text": [
            "ERROR:root:Internal Python error in the inspect module.\n",
            "Below is the traceback from this internal error.\n",
            "\n"
          ]
        },
        {
          "name": "stdout",
          "output_type": "stream",
          "text": [
            "Traceback (most recent call last):\n",
            "  File \"/usr/local/lib/python3.10/dist-packages/IPython/core/interactiveshell.py\", line 3553, in run_code\n",
            "    exec(code_obj, self.user_global_ns, self.user_ns)\n",
            "  File \"<ipython-input-10-1f5aa19bb70b>\", line 1, in <cell line: 1>\n",
            "    df_series['seriesvariable_standardname'] = df_series['seriesvariable_standardname'].str.replace('(',' ', regex = False).str.replace(')', '', regex = False)\n",
            "NameError: name 'df_series' is not defined\n",
            "\n",
            "During handling of the above exception, another exception occurred:\n",
            "\n",
            "Traceback (most recent call last):\n",
            "  File \"/usr/local/lib/python3.10/dist-packages/IPython/core/interactiveshell.py\", line 2099, in showtraceback\n",
            "    stb = value._render_traceback_()\n",
            "AttributeError: 'NameError' object has no attribute '_render_traceback_'\n",
            "\n",
            "During handling of the above exception, another exception occurred:\n",
            "\n",
            "Traceback (most recent call last):\n",
            "  File \"/usr/local/lib/python3.10/dist-packages/IPython/core/interactiveshell.py\", line 3473, in run_ast_nodes\n",
            "    if (await self.run_code(code, result,  async_=asy)):\n",
            "  File \"/usr/local/lib/python3.10/dist-packages/IPython/core/interactiveshell.py\", line 3575, in run_code\n",
            "    self.showtraceback(running_compiled_code=True)\n",
            "  File \"/usr/local/lib/python3.10/dist-packages/IPython/core/interactiveshell.py\", line 2101, in showtraceback\n",
            "    stb = self.InteractiveTB.structured_traceback(etype,\n",
            "  File \"/usr/local/lib/python3.10/dist-packages/IPython/core/ultratb.py\", line 1367, in structured_traceback\n",
            "    return FormattedTB.structured_traceback(\n",
            "  File \"/usr/local/lib/python3.10/dist-packages/IPython/core/ultratb.py\", line 1267, in structured_traceback\n",
            "    return VerboseTB.structured_traceback(\n",
            "  File \"/usr/local/lib/python3.10/dist-packages/IPython/core/ultratb.py\", line 1124, in structured_traceback\n",
            "    formatted_exception = self.format_exception_as_a_whole(etype, evalue, etb, number_of_lines_of_context,\n",
            "  File \"/usr/local/lib/python3.10/dist-packages/IPython/core/ultratb.py\", line 1082, in format_exception_as_a_whole\n",
            "    last_unique, recursion_repeat = find_recursion(orig_etype, evalue, records)\n",
            "  File \"/usr/local/lib/python3.10/dist-packages/IPython/core/ultratb.py\", line 382, in find_recursion\n",
            "    return len(records), 0\n",
            "TypeError: object of type 'NoneType' has no len()\n",
            "\n",
            "During handling of the above exception, another exception occurred:\n",
            "\n",
            "Traceback (most recent call last):\n",
            "  File \"/usr/local/lib/python3.10/dist-packages/IPython/core/interactiveshell.py\", line 2099, in showtraceback\n",
            "    stb = value._render_traceback_()\n",
            "AttributeError: 'TypeError' object has no attribute '_render_traceback_'\n",
            "\n",
            "During handling of the above exception, another exception occurred:\n",
            "\n",
            "Traceback (most recent call last):\n",
            "  File \"/usr/local/lib/python3.10/dist-packages/IPython/core/interactiveshell.py\", line 3030, in _run_cell\n",
            "    return runner(coro)\n",
            "  File \"/usr/local/lib/python3.10/dist-packages/IPython/core/async_helpers.py\", line 78, in _pseudo_sync_runner\n",
            "    coro.send(None)\n",
            "  File \"/usr/local/lib/python3.10/dist-packages/IPython/core/interactiveshell.py\", line 3257, in run_cell_async\n",
            "    has_raised = await self.run_ast_nodes(code_ast.body, cell_name,\n",
            "  File \"/usr/local/lib/python3.10/dist-packages/IPython/core/interactiveshell.py\", line 3492, in run_ast_nodes\n",
            "    self.showtraceback()\n",
            "  File \"/usr/local/lib/python3.10/dist-packages/IPython/core/interactiveshell.py\", line 2101, in showtraceback\n",
            "    stb = self.InteractiveTB.structured_traceback(etype,\n",
            "  File \"/usr/local/lib/python3.10/dist-packages/IPython/core/ultratb.py\", line 1367, in structured_traceback\n",
            "    return FormattedTB.structured_traceback(\n",
            "  File \"/usr/local/lib/python3.10/dist-packages/IPython/core/ultratb.py\", line 1267, in structured_traceback\n",
            "    return VerboseTB.structured_traceback(\n",
            "  File \"/usr/local/lib/python3.10/dist-packages/IPython/core/ultratb.py\", line 1142, in structured_traceback\n",
            "    formatted_exceptions += self.format_exception_as_a_whole(etype, evalue, etb, lines_of_context,\n",
            "  File \"/usr/local/lib/python3.10/dist-packages/IPython/core/ultratb.py\", line 1082, in format_exception_as_a_whole\n",
            "    last_unique, recursion_repeat = find_recursion(orig_etype, evalue, records)\n",
            "  File \"/usr/local/lib/python3.10/dist-packages/IPython/core/ultratb.py\", line 382, in find_recursion\n",
            "    return len(records), 0\n",
            "TypeError: object of type 'NoneType' has no len()\n",
            "\n",
            "During handling of the above exception, another exception occurred:\n",
            "\n",
            "Traceback (most recent call last):\n",
            "  File \"/usr/local/lib/python3.10/dist-packages/IPython/core/interactiveshell.py\", line 2099, in showtraceback\n",
            "    stb = value._render_traceback_()\n",
            "AttributeError: 'TypeError' object has no attribute '_render_traceback_'\n",
            "\n",
            "During handling of the above exception, another exception occurred:\n",
            "\n",
            "Traceback (most recent call last):\n",
            "  File \"/usr/local/lib/python3.10/dist-packages/IPython/core/ultratb.py\", line 1101, in get_records\n",
            "    return _fixed_getinnerframes(etb, number_of_lines_of_context, tb_offset)\n",
            "  File \"/usr/local/lib/python3.10/dist-packages/IPython/core/ultratb.py\", line 248, in wrapped\n",
            "    return f(*args, **kwargs)\n",
            "  File \"/usr/local/lib/python3.10/dist-packages/IPython/core/ultratb.py\", line 281, in _fixed_getinnerframes\n",
            "    records = fix_frame_records_filenames(inspect.getinnerframes(etb, context))\n",
            "  File \"/usr/lib/python3.10/inspect.py\", line 1662, in getinnerframes\n",
            "    frameinfo = (tb.tb_frame,) + getframeinfo(tb, context)\n",
            "  File \"/usr/lib/python3.10/inspect.py\", line 1620, in getframeinfo\n",
            "    filename = getsourcefile(frame) or getfile(frame)\n",
            "  File \"/usr/lib/python3.10/inspect.py\", line 829, in getsourcefile\n",
            "    module = getmodule(object, filename)\n",
            "  File \"/usr/lib/python3.10/inspect.py\", line 861, in getmodule\n",
            "    file = getabsfile(object, _filename)\n",
            "  File \"/usr/lib/python3.10/inspect.py\", line 845, in getabsfile\n",
            "    return os.path.normcase(os.path.abspath(_filename))\n",
            "  File \"/usr/lib/python3.10/posixpath.py\", line 384, in abspath\n",
            "    cwd = os.getcwd()\n",
            "OSError: [Errno 107] Transport endpoint is not connected\n"
          ]
        }
      ],
      "source": [
        "df_series['seriesvariable_standardname'] = df_series['seriesvariable_standardname'].str.replace('(',' ', regex = False).str.replace(')', '', regex = False)\n",
        "df_series[['name', 'type', 'period']] = df_series['seriesvariable_standardname'].str.split(' ', n = 2, expand = True)\n",
        "df_series = df_series.drop('seriesvariable_standardname', axis=1)"
      ],
      "id": "cd0e9fb2-37cd-425f-8518-df63650eb179"
    },
    {
      "cell_type": "code",
      "execution_count": null,
      "metadata": {
        "colab": {
          "background_save": true,
          "base_uri": "https://localhost:8080/",
          "height": 592
        },
        "id": "92bafe79-e610-44fd-9d60-d8ce5ffff26f",
        "outputId": "988aef05-9289-480b-8811-ef216877e125"
      },
      "outputs": [
        {
          "name": "stderr",
          "output_type": "stream",
          "text": [
            "ERROR:root:Internal Python error in the inspect module.\n",
            "Below is the traceback from this internal error.\n",
            "\n",
            "ERROR:root:Internal Python error in the inspect module.\n",
            "Below is the traceback from this internal error.\n",
            "\n"
          ]
        },
        {
          "name": "stdout",
          "output_type": "stream",
          "text": [
            "Traceback (most recent call last):\n",
            "  File \"/usr/local/lib/python3.10/dist-packages/IPython/core/interactiveshell.py\", line 3553, in run_code\n",
            "    exec(code_obj, self.user_global_ns, self.user_ns)\n",
            "  File \"<ipython-input-10-9ac93b20b22f>\", line 1, in <cell line: 1>\n",
            "    df_seriesdata = pd.merge(df_seriesdata, df_series[['name', 'type', 'period', 'unit_symbol', 'series_id', 'seriesvariable_longname']], on = 'series_id', how = 'left')\n",
            "NameError: name 'pd' is not defined\n",
            "\n",
            "During handling of the above exception, another exception occurred:\n",
            "\n",
            "Traceback (most recent call last):\n",
            "  File \"/usr/local/lib/python3.10/dist-packages/IPython/core/interactiveshell.py\", line 2099, in showtraceback\n",
            "    stb = value._render_traceback_()\n",
            "AttributeError: 'NameError' object has no attribute '_render_traceback_'\n",
            "\n",
            "During handling of the above exception, another exception occurred:\n",
            "\n",
            "Traceback (most recent call last):\n",
            "  File \"/usr/local/lib/python3.10/dist-packages/IPython/core/ultratb.py\", line 1101, in get_records\n",
            "    return _fixed_getinnerframes(etb, number_of_lines_of_context, tb_offset)\n",
            "  File \"/usr/local/lib/python3.10/dist-packages/IPython/core/ultratb.py\", line 248, in wrapped\n",
            "    return f(*args, **kwargs)\n",
            "  File \"/usr/local/lib/python3.10/dist-packages/IPython/core/ultratb.py\", line 281, in _fixed_getinnerframes\n",
            "    records = fix_frame_records_filenames(inspect.getinnerframes(etb, context))\n",
            "  File \"/usr/lib/python3.10/inspect.py\", line 1662, in getinnerframes\n",
            "    frameinfo = (tb.tb_frame,) + getframeinfo(tb, context)\n",
            "  File \"/usr/lib/python3.10/inspect.py\", line 1620, in getframeinfo\n",
            "    filename = getsourcefile(frame) or getfile(frame)\n",
            "  File \"/usr/lib/python3.10/inspect.py\", line 829, in getsourcefile\n",
            "    module = getmodule(object, filename)\n",
            "  File \"/usr/lib/python3.10/inspect.py\", line 861, in getmodule\n",
            "    file = getabsfile(object, _filename)\n",
            "  File \"/usr/lib/python3.10/inspect.py\", line 845, in getabsfile\n",
            "    return os.path.normcase(os.path.abspath(_filename))\n",
            "  File \"/usr/lib/python3.10/posixpath.py\", line 384, in abspath\n",
            "    cwd = os.getcwd()\n",
            "OSError: [Errno 107] Transport endpoint is not connected\n",
            "Traceback (most recent call last):\n",
            "  File \"/usr/local/lib/python3.10/dist-packages/IPython/core/interactiveshell.py\", line 3553, in run_code\n",
            "    exec(code_obj, self.user_global_ns, self.user_ns)\n",
            "  File \"<ipython-input-10-9ac93b20b22f>\", line 1, in <cell line: 1>\n",
            "    df_seriesdata = pd.merge(df_seriesdata, df_series[['name', 'type', 'period', 'unit_symbol', 'series_id', 'seriesvariable_longname']], on = 'series_id', how = 'left')\n",
            "NameError: name 'pd' is not defined\n",
            "\n",
            "During handling of the above exception, another exception occurred:\n",
            "\n",
            "Traceback (most recent call last):\n",
            "  File \"/usr/local/lib/python3.10/dist-packages/IPython/core/interactiveshell.py\", line 2099, in showtraceback\n",
            "    stb = value._render_traceback_()\n",
            "AttributeError: 'NameError' object has no attribute '_render_traceback_'\n",
            "\n",
            "During handling of the above exception, another exception occurred:\n",
            "\n",
            "Traceback (most recent call last):\n",
            "  File \"/usr/local/lib/python3.10/dist-packages/IPython/core/interactiveshell.py\", line 3473, in run_ast_nodes\n",
            "    if (await self.run_code(code, result,  async_=asy)):\n",
            "  File \"/usr/local/lib/python3.10/dist-packages/IPython/core/interactiveshell.py\", line 3575, in run_code\n",
            "    self.showtraceback(running_compiled_code=True)\n",
            "  File \"/usr/local/lib/python3.10/dist-packages/IPython/core/interactiveshell.py\", line 2101, in showtraceback\n",
            "    stb = self.InteractiveTB.structured_traceback(etype,\n",
            "  File \"/usr/local/lib/python3.10/dist-packages/IPython/core/ultratb.py\", line 1367, in structured_traceback\n",
            "    return FormattedTB.structured_traceback(\n",
            "  File \"/usr/local/lib/python3.10/dist-packages/IPython/core/ultratb.py\", line 1267, in structured_traceback\n",
            "    return VerboseTB.structured_traceback(\n",
            "  File \"/usr/local/lib/python3.10/dist-packages/IPython/core/ultratb.py\", line 1124, in structured_traceback\n",
            "    formatted_exception = self.format_exception_as_a_whole(etype, evalue, etb, number_of_lines_of_context,\n",
            "  File \"/usr/local/lib/python3.10/dist-packages/IPython/core/ultratb.py\", line 1082, in format_exception_as_a_whole\n",
            "    last_unique, recursion_repeat = find_recursion(orig_etype, evalue, records)\n",
            "  File \"/usr/local/lib/python3.10/dist-packages/IPython/core/ultratb.py\", line 382, in find_recursion\n",
            "    return len(records), 0\n",
            "TypeError: object of type 'NoneType' has no len()\n",
            "\n",
            "During handling of the above exception, another exception occurred:\n",
            "\n",
            "Traceback (most recent call last):\n",
            "  File \"/usr/local/lib/python3.10/dist-packages/IPython/core/interactiveshell.py\", line 2099, in showtraceback\n",
            "    stb = value._render_traceback_()\n",
            "AttributeError: 'TypeError' object has no attribute '_render_traceback_'\n",
            "\n",
            "During handling of the above exception, another exception occurred:\n",
            "\n",
            "Traceback (most recent call last):\n",
            "  File \"/usr/local/lib/python3.10/dist-packages/IPython/core/ultratb.py\", line 1101, in get_records\n",
            "    return _fixed_getinnerframes(etb, number_of_lines_of_context, tb_offset)\n",
            "  File \"/usr/local/lib/python3.10/dist-packages/IPython/core/ultratb.py\", line 248, in wrapped\n",
            "    return f(*args, **kwargs)\n",
            "  File \"/usr/local/lib/python3.10/dist-packages/IPython/core/ultratb.py\", line 281, in _fixed_getinnerframes\n",
            "    records = fix_frame_records_filenames(inspect.getinnerframes(etb, context))\n",
            "  File \"/usr/lib/python3.10/inspect.py\", line 1662, in getinnerframes\n",
            "    frameinfo = (tb.tb_frame,) + getframeinfo(tb, context)\n",
            "  File \"/usr/lib/python3.10/inspect.py\", line 1620, in getframeinfo\n",
            "    filename = getsourcefile(frame) or getfile(frame)\n",
            "  File \"/usr/lib/python3.10/inspect.py\", line 829, in getsourcefile\n",
            "    module = getmodule(object, filename)\n",
            "  File \"/usr/lib/python3.10/inspect.py\", line 861, in getmodule\n",
            "    file = getabsfile(object, _filename)\n",
            "  File \"/usr/lib/python3.10/inspect.py\", line 845, in getabsfile\n",
            "    return os.path.normcase(os.path.abspath(_filename))\n",
            "  File \"/usr/lib/python3.10/posixpath.py\", line 384, in abspath\n",
            "    cwd = os.getcwd()\n",
            "OSError: [Errno 107] Transport endpoint is not connected\n"
          ]
        },
        {
          "name": "stderr",
          "output_type": "stream",
          "text": [
            "ERROR:root:Internal Python error in the inspect module.\n",
            "Below is the traceback from this internal error.\n",
            "\n"
          ]
        },
        {
          "name": "stdout",
          "output_type": "stream",
          "text": [
            "Traceback (most recent call last):\n",
            "  File \"/usr/local/lib/python3.10/dist-packages/IPython/core/interactiveshell.py\", line 3553, in run_code\n",
            "    exec(code_obj, self.user_global_ns, self.user_ns)\n",
            "  File \"<ipython-input-10-9ac93b20b22f>\", line 1, in <cell line: 1>\n",
            "    df_seriesdata = pd.merge(df_seriesdata, df_series[['name', 'type', 'period', 'unit_symbol', 'series_id', 'seriesvariable_longname']], on = 'series_id', how = 'left')\n",
            "NameError: name 'pd' is not defined\n",
            "\n",
            "During handling of the above exception, another exception occurred:\n",
            "\n",
            "Traceback (most recent call last):\n",
            "  File \"/usr/local/lib/python3.10/dist-packages/IPython/core/interactiveshell.py\", line 2099, in showtraceback\n",
            "    stb = value._render_traceback_()\n",
            "AttributeError: 'NameError' object has no attribute '_render_traceback_'\n",
            "\n",
            "During handling of the above exception, another exception occurred:\n",
            "\n",
            "Traceback (most recent call last):\n",
            "  File \"/usr/local/lib/python3.10/dist-packages/IPython/core/interactiveshell.py\", line 3473, in run_ast_nodes\n",
            "    if (await self.run_code(code, result,  async_=asy)):\n",
            "  File \"/usr/local/lib/python3.10/dist-packages/IPython/core/interactiveshell.py\", line 3575, in run_code\n",
            "    self.showtraceback(running_compiled_code=True)\n",
            "  File \"/usr/local/lib/python3.10/dist-packages/IPython/core/interactiveshell.py\", line 2101, in showtraceback\n",
            "    stb = self.InteractiveTB.structured_traceback(etype,\n",
            "  File \"/usr/local/lib/python3.10/dist-packages/IPython/core/ultratb.py\", line 1367, in structured_traceback\n",
            "    return FormattedTB.structured_traceback(\n",
            "  File \"/usr/local/lib/python3.10/dist-packages/IPython/core/ultratb.py\", line 1267, in structured_traceback\n",
            "    return VerboseTB.structured_traceback(\n",
            "  File \"/usr/local/lib/python3.10/dist-packages/IPython/core/ultratb.py\", line 1124, in structured_traceback\n",
            "    formatted_exception = self.format_exception_as_a_whole(etype, evalue, etb, number_of_lines_of_context,\n",
            "  File \"/usr/local/lib/python3.10/dist-packages/IPython/core/ultratb.py\", line 1082, in format_exception_as_a_whole\n",
            "    last_unique, recursion_repeat = find_recursion(orig_etype, evalue, records)\n",
            "  File \"/usr/local/lib/python3.10/dist-packages/IPython/core/ultratb.py\", line 382, in find_recursion\n",
            "    return len(records), 0\n",
            "TypeError: object of type 'NoneType' has no len()\n",
            "\n",
            "During handling of the above exception, another exception occurred:\n",
            "\n",
            "Traceback (most recent call last):\n",
            "  File \"/usr/local/lib/python3.10/dist-packages/IPython/core/interactiveshell.py\", line 2099, in showtraceback\n",
            "    stb = value._render_traceback_()\n",
            "AttributeError: 'TypeError' object has no attribute '_render_traceback_'\n",
            "\n",
            "During handling of the above exception, another exception occurred:\n",
            "\n",
            "Traceback (most recent call last):\n",
            "  File \"/usr/local/lib/python3.10/dist-packages/IPython/core/interactiveshell.py\", line 3030, in _run_cell\n",
            "    return runner(coro)\n",
            "  File \"/usr/local/lib/python3.10/dist-packages/IPython/core/async_helpers.py\", line 78, in _pseudo_sync_runner\n",
            "    coro.send(None)\n",
            "  File \"/usr/local/lib/python3.10/dist-packages/IPython/core/interactiveshell.py\", line 3257, in run_cell_async\n",
            "    has_raised = await self.run_ast_nodes(code_ast.body, cell_name,\n",
            "  File \"/usr/local/lib/python3.10/dist-packages/IPython/core/interactiveshell.py\", line 3492, in run_ast_nodes\n",
            "    self.showtraceback()\n",
            "  File \"/usr/local/lib/python3.10/dist-packages/IPython/core/interactiveshell.py\", line 2101, in showtraceback\n",
            "    stb = self.InteractiveTB.structured_traceback(etype,\n",
            "  File \"/usr/local/lib/python3.10/dist-packages/IPython/core/ultratb.py\", line 1367, in structured_traceback\n",
            "    return FormattedTB.structured_traceback(\n",
            "  File \"/usr/local/lib/python3.10/dist-packages/IPython/core/ultratb.py\", line 1267, in structured_traceback\n",
            "    return VerboseTB.structured_traceback(\n",
            "  File \"/usr/local/lib/python3.10/dist-packages/IPython/core/ultratb.py\", line 1142, in structured_traceback\n",
            "    formatted_exceptions += self.format_exception_as_a_whole(etype, evalue, etb, lines_of_context,\n",
            "  File \"/usr/local/lib/python3.10/dist-packages/IPython/core/ultratb.py\", line 1082, in format_exception_as_a_whole\n",
            "    last_unique, recursion_repeat = find_recursion(orig_etype, evalue, records)\n",
            "  File \"/usr/local/lib/python3.10/dist-packages/IPython/core/ultratb.py\", line 382, in find_recursion\n",
            "    return len(records), 0\n",
            "TypeError: object of type 'NoneType' has no len()\n",
            "\n",
            "During handling of the above exception, another exception occurred:\n",
            "\n",
            "Traceback (most recent call last):\n",
            "  File \"/usr/local/lib/python3.10/dist-packages/IPython/core/interactiveshell.py\", line 2099, in showtraceback\n",
            "    stb = value._render_traceback_()\n",
            "AttributeError: 'TypeError' object has no attribute '_render_traceback_'\n",
            "\n",
            "During handling of the above exception, another exception occurred:\n",
            "\n",
            "Traceback (most recent call last):\n",
            "  File \"/usr/local/lib/python3.10/dist-packages/IPython/core/ultratb.py\", line 1101, in get_records\n",
            "    return _fixed_getinnerframes(etb, number_of_lines_of_context, tb_offset)\n",
            "  File \"/usr/local/lib/python3.10/dist-packages/IPython/core/ultratb.py\", line 248, in wrapped\n",
            "    return f(*args, **kwargs)\n",
            "  File \"/usr/local/lib/python3.10/dist-packages/IPython/core/ultratb.py\", line 281, in _fixed_getinnerframes\n",
            "    records = fix_frame_records_filenames(inspect.getinnerframes(etb, context))\n",
            "  File \"/usr/lib/python3.10/inspect.py\", line 1662, in getinnerframes\n",
            "    frameinfo = (tb.tb_frame,) + getframeinfo(tb, context)\n",
            "  File \"/usr/lib/python3.10/inspect.py\", line 1620, in getframeinfo\n",
            "    filename = getsourcefile(frame) or getfile(frame)\n",
            "  File \"/usr/lib/python3.10/inspect.py\", line 829, in getsourcefile\n",
            "    module = getmodule(object, filename)\n",
            "  File \"/usr/lib/python3.10/inspect.py\", line 861, in getmodule\n",
            "    file = getabsfile(object, _filename)\n",
            "  File \"/usr/lib/python3.10/inspect.py\", line 845, in getabsfile\n",
            "    return os.path.normcase(os.path.abspath(_filename))\n",
            "  File \"/usr/lib/python3.10/posixpath.py\", line 384, in abspath\n",
            "    cwd = os.getcwd()\n",
            "OSError: [Errno 107] Transport endpoint is not connected\n"
          ]
        }
      ],
      "source": [
        "df_seriesdata = pd.merge(df_seriesdata, df_series[['name', 'type', 'period', 'unit_symbol', 'series_id', 'seriesvariable_longname']], on = 'series_id', how = 'left')\n",
        "df_seriesdata"
      ],
      "id": "92bafe79-e610-44fd-9d60-d8ce5ffff26f"
    },
    {
      "cell_type": "code",
      "execution_count": null,
      "metadata": {
        "colab": {
          "background_save": true,
          "base_uri": "https://localhost:8080/",
          "height": 592
        },
        "id": "368b2104-8d7a-4196-975b-019f4495cc9e",
        "outputId": "3d345fd0-366b-40eb-cc3f-a56b2adff5d4"
      },
      "outputs": [
        {
          "name": "stderr",
          "output_type": "stream",
          "text": [
            "ERROR:root:Internal Python error in the inspect module.\n",
            "Below is the traceback from this internal error.\n",
            "\n",
            "ERROR:root:Internal Python error in the inspect module.\n",
            "Below is the traceback from this internal error.\n",
            "\n"
          ]
        },
        {
          "name": "stdout",
          "output_type": "stream",
          "text": [
            "Traceback (most recent call last):\n",
            "  File \"/usr/local/lib/python3.10/dist-packages/IPython/core/interactiveshell.py\", line 3553, in run_code\n",
            "    exec(code_obj, self.user_global_ns, self.user_ns)\n",
            "  File \"<ipython-input-10-a38b998e92c7>\", line 1, in <cell line: 1>\n",
            "    df_seriesdata = pd.merge(df_seriesdata, df_datasources[['datasource_id', 'datasource_name', 'datasourcetype_name','longitude','latitude', 'datasource_externalid']], on = 'datasource_externalid', how = 'left')\n",
            "NameError: name 'pd' is not defined\n",
            "\n",
            "During handling of the above exception, another exception occurred:\n",
            "\n",
            "Traceback (most recent call last):\n",
            "  File \"/usr/local/lib/python3.10/dist-packages/IPython/core/interactiveshell.py\", line 2099, in showtraceback\n",
            "    stb = value._render_traceback_()\n",
            "AttributeError: 'NameError' object has no attribute '_render_traceback_'\n",
            "\n",
            "During handling of the above exception, another exception occurred:\n",
            "\n",
            "Traceback (most recent call last):\n",
            "  File \"/usr/local/lib/python3.10/dist-packages/IPython/core/ultratb.py\", line 1101, in get_records\n",
            "    return _fixed_getinnerframes(etb, number_of_lines_of_context, tb_offset)\n",
            "  File \"/usr/local/lib/python3.10/dist-packages/IPython/core/ultratb.py\", line 248, in wrapped\n",
            "    return f(*args, **kwargs)\n",
            "  File \"/usr/local/lib/python3.10/dist-packages/IPython/core/ultratb.py\", line 281, in _fixed_getinnerframes\n",
            "    records = fix_frame_records_filenames(inspect.getinnerframes(etb, context))\n",
            "  File \"/usr/lib/python3.10/inspect.py\", line 1662, in getinnerframes\n",
            "    frameinfo = (tb.tb_frame,) + getframeinfo(tb, context)\n",
            "  File \"/usr/lib/python3.10/inspect.py\", line 1620, in getframeinfo\n",
            "    filename = getsourcefile(frame) or getfile(frame)\n",
            "  File \"/usr/lib/python3.10/inspect.py\", line 829, in getsourcefile\n",
            "    module = getmodule(object, filename)\n",
            "  File \"/usr/lib/python3.10/inspect.py\", line 861, in getmodule\n",
            "    file = getabsfile(object, _filename)\n",
            "  File \"/usr/lib/python3.10/inspect.py\", line 845, in getabsfile\n",
            "    return os.path.normcase(os.path.abspath(_filename))\n",
            "  File \"/usr/lib/python3.10/posixpath.py\", line 384, in abspath\n",
            "    cwd = os.getcwd()\n",
            "OSError: [Errno 107] Transport endpoint is not connected\n",
            "Traceback (most recent call last):\n",
            "  File \"/usr/local/lib/python3.10/dist-packages/IPython/core/interactiveshell.py\", line 3553, in run_code\n",
            "    exec(code_obj, self.user_global_ns, self.user_ns)\n",
            "  File \"<ipython-input-10-a38b998e92c7>\", line 1, in <cell line: 1>\n",
            "    df_seriesdata = pd.merge(df_seriesdata, df_datasources[['datasource_id', 'datasource_name', 'datasourcetype_name','longitude','latitude', 'datasource_externalid']], on = 'datasource_externalid', how = 'left')\n",
            "NameError: name 'pd' is not defined\n",
            "\n",
            "During handling of the above exception, another exception occurred:\n",
            "\n",
            "Traceback (most recent call last):\n",
            "  File \"/usr/local/lib/python3.10/dist-packages/IPython/core/interactiveshell.py\", line 2099, in showtraceback\n",
            "    stb = value._render_traceback_()\n",
            "AttributeError: 'NameError' object has no attribute '_render_traceback_'\n",
            "\n",
            "During handling of the above exception, another exception occurred:\n",
            "\n",
            "Traceback (most recent call last):\n",
            "  File \"/usr/local/lib/python3.10/dist-packages/IPython/core/interactiveshell.py\", line 3473, in run_ast_nodes\n",
            "    if (await self.run_code(code, result,  async_=asy)):\n",
            "  File \"/usr/local/lib/python3.10/dist-packages/IPython/core/interactiveshell.py\", line 3575, in run_code\n",
            "    self.showtraceback(running_compiled_code=True)\n",
            "  File \"/usr/local/lib/python3.10/dist-packages/IPython/core/interactiveshell.py\", line 2101, in showtraceback\n",
            "    stb = self.InteractiveTB.structured_traceback(etype,\n",
            "  File \"/usr/local/lib/python3.10/dist-packages/IPython/core/ultratb.py\", line 1367, in structured_traceback\n",
            "    return FormattedTB.structured_traceback(\n",
            "  File \"/usr/local/lib/python3.10/dist-packages/IPython/core/ultratb.py\", line 1267, in structured_traceback\n",
            "    return VerboseTB.structured_traceback(\n",
            "  File \"/usr/local/lib/python3.10/dist-packages/IPython/core/ultratb.py\", line 1124, in structured_traceback\n",
            "    formatted_exception = self.format_exception_as_a_whole(etype, evalue, etb, number_of_lines_of_context,\n",
            "  File \"/usr/local/lib/python3.10/dist-packages/IPython/core/ultratb.py\", line 1082, in format_exception_as_a_whole\n",
            "    last_unique, recursion_repeat = find_recursion(orig_etype, evalue, records)\n",
            "  File \"/usr/local/lib/python3.10/dist-packages/IPython/core/ultratb.py\", line 382, in find_recursion\n",
            "    return len(records), 0\n",
            "TypeError: object of type 'NoneType' has no len()\n",
            "\n",
            "During handling of the above exception, another exception occurred:\n",
            "\n",
            "Traceback (most recent call last):\n",
            "  File \"/usr/local/lib/python3.10/dist-packages/IPython/core/interactiveshell.py\", line 2099, in showtraceback\n",
            "    stb = value._render_traceback_()\n",
            "AttributeError: 'TypeError' object has no attribute '_render_traceback_'\n",
            "\n",
            "During handling of the above exception, another exception occurred:\n",
            "\n",
            "Traceback (most recent call last):\n",
            "  File \"/usr/local/lib/python3.10/dist-packages/IPython/core/ultratb.py\", line 1101, in get_records\n",
            "    return _fixed_getinnerframes(etb, number_of_lines_of_context, tb_offset)\n",
            "  File \"/usr/local/lib/python3.10/dist-packages/IPython/core/ultratb.py\", line 248, in wrapped\n",
            "    return f(*args, **kwargs)\n",
            "  File \"/usr/local/lib/python3.10/dist-packages/IPython/core/ultratb.py\", line 281, in _fixed_getinnerframes\n",
            "    records = fix_frame_records_filenames(inspect.getinnerframes(etb, context))\n",
            "  File \"/usr/lib/python3.10/inspect.py\", line 1662, in getinnerframes\n",
            "    frameinfo = (tb.tb_frame,) + getframeinfo(tb, context)\n",
            "  File \"/usr/lib/python3.10/inspect.py\", line 1620, in getframeinfo\n",
            "    filename = getsourcefile(frame) or getfile(frame)\n",
            "  File \"/usr/lib/python3.10/inspect.py\", line 829, in getsourcefile\n",
            "    module = getmodule(object, filename)\n",
            "  File \"/usr/lib/python3.10/inspect.py\", line 861, in getmodule\n",
            "    file = getabsfile(object, _filename)\n",
            "  File \"/usr/lib/python3.10/inspect.py\", line 845, in getabsfile\n",
            "    return os.path.normcase(os.path.abspath(_filename))\n",
            "  File \"/usr/lib/python3.10/posixpath.py\", line 384, in abspath\n",
            "    cwd = os.getcwd()\n",
            "OSError: [Errno 107] Transport endpoint is not connected\n"
          ]
        },
        {
          "name": "stderr",
          "output_type": "stream",
          "text": [
            "ERROR:root:Internal Python error in the inspect module.\n",
            "Below is the traceback from this internal error.\n",
            "\n"
          ]
        },
        {
          "name": "stdout",
          "output_type": "stream",
          "text": [
            "Traceback (most recent call last):\n",
            "  File \"/usr/local/lib/python3.10/dist-packages/IPython/core/interactiveshell.py\", line 3553, in run_code\n",
            "    exec(code_obj, self.user_global_ns, self.user_ns)\n",
            "  File \"<ipython-input-10-a38b998e92c7>\", line 1, in <cell line: 1>\n",
            "    df_seriesdata = pd.merge(df_seriesdata, df_datasources[['datasource_id', 'datasource_name', 'datasourcetype_name','longitude','latitude', 'datasource_externalid']], on = 'datasource_externalid', how = 'left')\n",
            "NameError: name 'pd' is not defined\n",
            "\n",
            "During handling of the above exception, another exception occurred:\n",
            "\n",
            "Traceback (most recent call last):\n",
            "  File \"/usr/local/lib/python3.10/dist-packages/IPython/core/interactiveshell.py\", line 2099, in showtraceback\n",
            "    stb = value._render_traceback_()\n",
            "AttributeError: 'NameError' object has no attribute '_render_traceback_'\n",
            "\n",
            "During handling of the above exception, another exception occurred:\n",
            "\n",
            "Traceback (most recent call last):\n",
            "  File \"/usr/local/lib/python3.10/dist-packages/IPython/core/interactiveshell.py\", line 3473, in run_ast_nodes\n",
            "    if (await self.run_code(code, result,  async_=asy)):\n",
            "  File \"/usr/local/lib/python3.10/dist-packages/IPython/core/interactiveshell.py\", line 3575, in run_code\n",
            "    self.showtraceback(running_compiled_code=True)\n",
            "  File \"/usr/local/lib/python3.10/dist-packages/IPython/core/interactiveshell.py\", line 2101, in showtraceback\n",
            "    stb = self.InteractiveTB.structured_traceback(etype,\n",
            "  File \"/usr/local/lib/python3.10/dist-packages/IPython/core/ultratb.py\", line 1367, in structured_traceback\n",
            "    return FormattedTB.structured_traceback(\n",
            "  File \"/usr/local/lib/python3.10/dist-packages/IPython/core/ultratb.py\", line 1267, in structured_traceback\n",
            "    return VerboseTB.structured_traceback(\n",
            "  File \"/usr/local/lib/python3.10/dist-packages/IPython/core/ultratb.py\", line 1124, in structured_traceback\n",
            "    formatted_exception = self.format_exception_as_a_whole(etype, evalue, etb, number_of_lines_of_context,\n",
            "  File \"/usr/local/lib/python3.10/dist-packages/IPython/core/ultratb.py\", line 1082, in format_exception_as_a_whole\n",
            "    last_unique, recursion_repeat = find_recursion(orig_etype, evalue, records)\n",
            "  File \"/usr/local/lib/python3.10/dist-packages/IPython/core/ultratb.py\", line 382, in find_recursion\n",
            "    return len(records), 0\n",
            "TypeError: object of type 'NoneType' has no len()\n",
            "\n",
            "During handling of the above exception, another exception occurred:\n",
            "\n",
            "Traceback (most recent call last):\n",
            "  File \"/usr/local/lib/python3.10/dist-packages/IPython/core/interactiveshell.py\", line 2099, in showtraceback\n",
            "    stb = value._render_traceback_()\n",
            "AttributeError: 'TypeError' object has no attribute '_render_traceback_'\n",
            "\n",
            "During handling of the above exception, another exception occurred:\n",
            "\n",
            "Traceback (most recent call last):\n",
            "  File \"/usr/local/lib/python3.10/dist-packages/IPython/core/interactiveshell.py\", line 3030, in _run_cell\n",
            "    return runner(coro)\n",
            "  File \"/usr/local/lib/python3.10/dist-packages/IPython/core/async_helpers.py\", line 78, in _pseudo_sync_runner\n",
            "    coro.send(None)\n",
            "  File \"/usr/local/lib/python3.10/dist-packages/IPython/core/interactiveshell.py\", line 3257, in run_cell_async\n",
            "    has_raised = await self.run_ast_nodes(code_ast.body, cell_name,\n",
            "  File \"/usr/local/lib/python3.10/dist-packages/IPython/core/interactiveshell.py\", line 3492, in run_ast_nodes\n",
            "    self.showtraceback()\n",
            "  File \"/usr/local/lib/python3.10/dist-packages/IPython/core/interactiveshell.py\", line 2101, in showtraceback\n",
            "    stb = self.InteractiveTB.structured_traceback(etype,\n",
            "  File \"/usr/local/lib/python3.10/dist-packages/IPython/core/ultratb.py\", line 1367, in structured_traceback\n",
            "    return FormattedTB.structured_traceback(\n",
            "  File \"/usr/local/lib/python3.10/dist-packages/IPython/core/ultratb.py\", line 1267, in structured_traceback\n",
            "    return VerboseTB.structured_traceback(\n",
            "  File \"/usr/local/lib/python3.10/dist-packages/IPython/core/ultratb.py\", line 1142, in structured_traceback\n",
            "    formatted_exceptions += self.format_exception_as_a_whole(etype, evalue, etb, lines_of_context,\n",
            "  File \"/usr/local/lib/python3.10/dist-packages/IPython/core/ultratb.py\", line 1082, in format_exception_as_a_whole\n",
            "    last_unique, recursion_repeat = find_recursion(orig_etype, evalue, records)\n",
            "  File \"/usr/local/lib/python3.10/dist-packages/IPython/core/ultratb.py\", line 382, in find_recursion\n",
            "    return len(records), 0\n",
            "TypeError: object of type 'NoneType' has no len()\n",
            "\n",
            "During handling of the above exception, another exception occurred:\n",
            "\n",
            "Traceback (most recent call last):\n",
            "  File \"/usr/local/lib/python3.10/dist-packages/IPython/core/interactiveshell.py\", line 2099, in showtraceback\n",
            "    stb = value._render_traceback_()\n",
            "AttributeError: 'TypeError' object has no attribute '_render_traceback_'\n",
            "\n",
            "During handling of the above exception, another exception occurred:\n",
            "\n",
            "Traceback (most recent call last):\n",
            "  File \"/usr/local/lib/python3.10/dist-packages/IPython/core/ultratb.py\", line 1101, in get_records\n",
            "    return _fixed_getinnerframes(etb, number_of_lines_of_context, tb_offset)\n",
            "  File \"/usr/local/lib/python3.10/dist-packages/IPython/core/ultratb.py\", line 248, in wrapped\n",
            "    return f(*args, **kwargs)\n",
            "  File \"/usr/local/lib/python3.10/dist-packages/IPython/core/ultratb.py\", line 281, in _fixed_getinnerframes\n",
            "    records = fix_frame_records_filenames(inspect.getinnerframes(etb, context))\n",
            "  File \"/usr/lib/python3.10/inspect.py\", line 1662, in getinnerframes\n",
            "    frameinfo = (tb.tb_frame,) + getframeinfo(tb, context)\n",
            "  File \"/usr/lib/python3.10/inspect.py\", line 1620, in getframeinfo\n",
            "    filename = getsourcefile(frame) or getfile(frame)\n",
            "  File \"/usr/lib/python3.10/inspect.py\", line 829, in getsourcefile\n",
            "    module = getmodule(object, filename)\n",
            "  File \"/usr/lib/python3.10/inspect.py\", line 861, in getmodule\n",
            "    file = getabsfile(object, _filename)\n",
            "  File \"/usr/lib/python3.10/inspect.py\", line 845, in getabsfile\n",
            "    return os.path.normcase(os.path.abspath(_filename))\n",
            "  File \"/usr/lib/python3.10/posixpath.py\", line 384, in abspath\n",
            "    cwd = os.getcwd()\n",
            "OSError: [Errno 107] Transport endpoint is not connected\n"
          ]
        }
      ],
      "source": [
        "df_seriesdata = pd.merge(df_seriesdata, df_datasources[['datasource_id', 'datasource_name', 'datasourcetype_name','longitude','latitude', 'datasource_externalid']], on = 'datasource_externalid', how = 'left')\n",
        "df_seriesdata"
      ],
      "id": "368b2104-8d7a-4196-975b-019f4495cc9e"
    },
    {
      "cell_type": "code",
      "execution_count": null,
      "metadata": {
        "colab": {
          "background_save": true
        },
        "id": "9eec5729-574f-48ee-90c8-568d11c01bea",
        "outputId": "cd8c153b-1b09-448d-f722-bce35ff273a6"
      },
      "outputs": [
        {
          "name": "stderr",
          "output_type": "stream",
          "text": [
            "ERROR:root:Internal Python error in the inspect module.\n",
            "Below is the traceback from this internal error.\n",
            "\n",
            "ERROR:root:Internal Python error in the inspect module.\n",
            "Below is the traceback from this internal error.\n",
            "\n"
          ]
        },
        {
          "name": "stdout",
          "output_type": "stream",
          "text": [
            "Traceback (most recent call last):\n",
            "  File \"/usr/local/lib/python3.10/dist-packages/IPython/core/interactiveshell.py\", line 3553, in run_code\n",
            "    exec(code_obj, self.user_global_ns, self.user_ns)\n",
            "  File \"<ipython-input-10-161b7a3aa24b>\", line 1, in <cell line: 1>\n",
            "    df_seriesdata['seriesdata_timestamp'] = pd.to_datetime(df_seriesdata['seriesdata_timestamp'])\n",
            "NameError: name 'pd' is not defined\n",
            "\n",
            "During handling of the above exception, another exception occurred:\n",
            "\n",
            "Traceback (most recent call last):\n",
            "  File \"/usr/local/lib/python3.10/dist-packages/IPython/core/interactiveshell.py\", line 2099, in showtraceback\n",
            "    stb = value._render_traceback_()\n",
            "AttributeError: 'NameError' object has no attribute '_render_traceback_'\n",
            "\n",
            "During handling of the above exception, another exception occurred:\n",
            "\n",
            "Traceback (most recent call last):\n",
            "  File \"/usr/local/lib/python3.10/dist-packages/IPython/core/ultratb.py\", line 1101, in get_records\n",
            "    return _fixed_getinnerframes(etb, number_of_lines_of_context, tb_offset)\n",
            "  File \"/usr/local/lib/python3.10/dist-packages/IPython/core/ultratb.py\", line 248, in wrapped\n",
            "    return f(*args, **kwargs)\n",
            "  File \"/usr/local/lib/python3.10/dist-packages/IPython/core/ultratb.py\", line 281, in _fixed_getinnerframes\n",
            "    records = fix_frame_records_filenames(inspect.getinnerframes(etb, context))\n",
            "  File \"/usr/lib/python3.10/inspect.py\", line 1662, in getinnerframes\n",
            "    frameinfo = (tb.tb_frame,) + getframeinfo(tb, context)\n",
            "  File \"/usr/lib/python3.10/inspect.py\", line 1620, in getframeinfo\n",
            "    filename = getsourcefile(frame) or getfile(frame)\n",
            "  File \"/usr/lib/python3.10/inspect.py\", line 829, in getsourcefile\n",
            "    module = getmodule(object, filename)\n",
            "  File \"/usr/lib/python3.10/inspect.py\", line 861, in getmodule\n",
            "    file = getabsfile(object, _filename)\n",
            "  File \"/usr/lib/python3.10/inspect.py\", line 845, in getabsfile\n",
            "    return os.path.normcase(os.path.abspath(_filename))\n",
            "  File \"/usr/lib/python3.10/posixpath.py\", line 384, in abspath\n",
            "    cwd = os.getcwd()\n",
            "OSError: [Errno 107] Transport endpoint is not connected\n",
            "Traceback (most recent call last):\n",
            "  File \"/usr/local/lib/python3.10/dist-packages/IPython/core/interactiveshell.py\", line 3553, in run_code\n",
            "    exec(code_obj, self.user_global_ns, self.user_ns)\n",
            "  File \"<ipython-input-10-161b7a3aa24b>\", line 1, in <cell line: 1>\n",
            "    df_seriesdata['seriesdata_timestamp'] = pd.to_datetime(df_seriesdata['seriesdata_timestamp'])\n",
            "NameError: name 'pd' is not defined\n",
            "\n",
            "During handling of the above exception, another exception occurred:\n",
            "\n",
            "Traceback (most recent call last):\n",
            "  File \"/usr/local/lib/python3.10/dist-packages/IPython/core/interactiveshell.py\", line 2099, in showtraceback\n",
            "    stb = value._render_traceback_()\n",
            "AttributeError: 'NameError' object has no attribute '_render_traceback_'\n",
            "\n",
            "During handling of the above exception, another exception occurred:\n",
            "\n",
            "Traceback (most recent call last):\n",
            "  File \"/usr/local/lib/python3.10/dist-packages/IPython/core/interactiveshell.py\", line 3473, in run_ast_nodes\n",
            "    if (await self.run_code(code, result,  async_=asy)):\n",
            "  File \"/usr/local/lib/python3.10/dist-packages/IPython/core/interactiveshell.py\", line 3575, in run_code\n",
            "    self.showtraceback(running_compiled_code=True)\n",
            "  File \"/usr/local/lib/python3.10/dist-packages/IPython/core/interactiveshell.py\", line 2101, in showtraceback\n",
            "    stb = self.InteractiveTB.structured_traceback(etype,\n",
            "  File \"/usr/local/lib/python3.10/dist-packages/IPython/core/ultratb.py\", line 1367, in structured_traceback\n",
            "    return FormattedTB.structured_traceback(\n",
            "  File \"/usr/local/lib/python3.10/dist-packages/IPython/core/ultratb.py\", line 1267, in structured_traceback\n",
            "    return VerboseTB.structured_traceback(\n",
            "  File \"/usr/local/lib/python3.10/dist-packages/IPython/core/ultratb.py\", line 1124, in structured_traceback\n",
            "    formatted_exception = self.format_exception_as_a_whole(etype, evalue, etb, number_of_lines_of_context,\n",
            "  File \"/usr/local/lib/python3.10/dist-packages/IPython/core/ultratb.py\", line 1082, in format_exception_as_a_whole\n",
            "    last_unique, recursion_repeat = find_recursion(orig_etype, evalue, records)\n",
            "  File \"/usr/local/lib/python3.10/dist-packages/IPython/core/ultratb.py\", line 382, in find_recursion\n",
            "    return len(records), 0\n",
            "TypeError: object of type 'NoneType' has no len()\n",
            "\n",
            "During handling of the above exception, another exception occurred:\n",
            "\n",
            "Traceback (most recent call last):\n",
            "  File \"/usr/local/lib/python3.10/dist-packages/IPython/core/interactiveshell.py\", line 2099, in showtraceback\n",
            "    stb = value._render_traceback_()\n",
            "AttributeError: 'TypeError' object has no attribute '_render_traceback_'\n",
            "\n",
            "During handling of the above exception, another exception occurred:\n",
            "\n",
            "Traceback (most recent call last):\n",
            "  File \"/usr/local/lib/python3.10/dist-packages/IPython/core/ultratb.py\", line 1101, in get_records\n",
            "    return _fixed_getinnerframes(etb, number_of_lines_of_context, tb_offset)\n",
            "  File \"/usr/local/lib/python3.10/dist-packages/IPython/core/ultratb.py\", line 248, in wrapped\n",
            "    return f(*args, **kwargs)\n",
            "  File \"/usr/local/lib/python3.10/dist-packages/IPython/core/ultratb.py\", line 281, in _fixed_getinnerframes\n",
            "    records = fix_frame_records_filenames(inspect.getinnerframes(etb, context))\n",
            "  File \"/usr/lib/python3.10/inspect.py\", line 1662, in getinnerframes\n",
            "    frameinfo = (tb.tb_frame,) + getframeinfo(tb, context)\n",
            "  File \"/usr/lib/python3.10/inspect.py\", line 1620, in getframeinfo\n",
            "    filename = getsourcefile(frame) or getfile(frame)\n",
            "  File \"/usr/lib/python3.10/inspect.py\", line 829, in getsourcefile\n",
            "    module = getmodule(object, filename)\n",
            "  File \"/usr/lib/python3.10/inspect.py\", line 861, in getmodule\n",
            "    file = getabsfile(object, _filename)\n",
            "  File \"/usr/lib/python3.10/inspect.py\", line 845, in getabsfile\n",
            "    return os.path.normcase(os.path.abspath(_filename))\n",
            "  File \"/usr/lib/python3.10/posixpath.py\", line 384, in abspath\n",
            "    cwd = os.getcwd()\n",
            "OSError: [Errno 107] Transport endpoint is not connected\n"
          ]
        },
        {
          "name": "stderr",
          "output_type": "stream",
          "text": [
            "ERROR:root:Internal Python error in the inspect module.\n",
            "Below is the traceback from this internal error.\n",
            "\n"
          ]
        },
        {
          "name": "stdout",
          "output_type": "stream",
          "text": [
            "Traceback (most recent call last):\n",
            "  File \"/usr/local/lib/python3.10/dist-packages/IPython/core/interactiveshell.py\", line 3553, in run_code\n",
            "    exec(code_obj, self.user_global_ns, self.user_ns)\n",
            "  File \"<ipython-input-10-161b7a3aa24b>\", line 1, in <cell line: 1>\n",
            "    df_seriesdata['seriesdata_timestamp'] = pd.to_datetime(df_seriesdata['seriesdata_timestamp'])\n",
            "NameError: name 'pd' is not defined\n",
            "\n",
            "During handling of the above exception, another exception occurred:\n",
            "\n",
            "Traceback (most recent call last):\n",
            "  File \"/usr/local/lib/python3.10/dist-packages/IPython/core/interactiveshell.py\", line 2099, in showtraceback\n",
            "    stb = value._render_traceback_()\n",
            "AttributeError: 'NameError' object has no attribute '_render_traceback_'\n",
            "\n",
            "During handling of the above exception, another exception occurred:\n",
            "\n",
            "Traceback (most recent call last):\n",
            "  File \"/usr/local/lib/python3.10/dist-packages/IPython/core/interactiveshell.py\", line 3473, in run_ast_nodes\n",
            "    if (await self.run_code(code, result,  async_=asy)):\n",
            "  File \"/usr/local/lib/python3.10/dist-packages/IPython/core/interactiveshell.py\", line 3575, in run_code\n",
            "    self.showtraceback(running_compiled_code=True)\n",
            "  File \"/usr/local/lib/python3.10/dist-packages/IPython/core/interactiveshell.py\", line 2101, in showtraceback\n",
            "    stb = self.InteractiveTB.structured_traceback(etype,\n",
            "  File \"/usr/local/lib/python3.10/dist-packages/IPython/core/ultratb.py\", line 1367, in structured_traceback\n",
            "    return FormattedTB.structured_traceback(\n",
            "  File \"/usr/local/lib/python3.10/dist-packages/IPython/core/ultratb.py\", line 1267, in structured_traceback\n",
            "    return VerboseTB.structured_traceback(\n",
            "  File \"/usr/local/lib/python3.10/dist-packages/IPython/core/ultratb.py\", line 1124, in structured_traceback\n",
            "    formatted_exception = self.format_exception_as_a_whole(etype, evalue, etb, number_of_lines_of_context,\n",
            "  File \"/usr/local/lib/python3.10/dist-packages/IPython/core/ultratb.py\", line 1082, in format_exception_as_a_whole\n",
            "    last_unique, recursion_repeat = find_recursion(orig_etype, evalue, records)\n",
            "  File \"/usr/local/lib/python3.10/dist-packages/IPython/core/ultratb.py\", line 382, in find_recursion\n",
            "    return len(records), 0\n",
            "TypeError: object of type 'NoneType' has no len()\n",
            "\n",
            "During handling of the above exception, another exception occurred:\n",
            "\n",
            "Traceback (most recent call last):\n",
            "  File \"/usr/local/lib/python3.10/dist-packages/IPython/core/interactiveshell.py\", line 2099, in showtraceback\n",
            "    stb = value._render_traceback_()\n",
            "AttributeError: 'TypeError' object has no attribute '_render_traceback_'\n",
            "\n",
            "During handling of the above exception, another exception occurred:\n",
            "\n",
            "Traceback (most recent call last):\n",
            "  File \"/usr/local/lib/python3.10/dist-packages/IPython/core/interactiveshell.py\", line 3030, in _run_cell\n",
            "    return runner(coro)\n",
            "  File \"/usr/local/lib/python3.10/dist-packages/IPython/core/async_helpers.py\", line 78, in _pseudo_sync_runner\n",
            "    coro.send(None)\n",
            "  File \"/usr/local/lib/python3.10/dist-packages/IPython/core/interactiveshell.py\", line 3257, in run_cell_async\n",
            "    has_raised = await self.run_ast_nodes(code_ast.body, cell_name,\n",
            "  File \"/usr/local/lib/python3.10/dist-packages/IPython/core/interactiveshell.py\", line 3492, in run_ast_nodes\n",
            "    self.showtraceback()\n",
            "  File \"/usr/local/lib/python3.10/dist-packages/IPython/core/interactiveshell.py\", line 2101, in showtraceback\n",
            "    stb = self.InteractiveTB.structured_traceback(etype,\n",
            "  File \"/usr/local/lib/python3.10/dist-packages/IPython/core/ultratb.py\", line 1367, in structured_traceback\n",
            "    return FormattedTB.structured_traceback(\n",
            "  File \"/usr/local/lib/python3.10/dist-packages/IPython/core/ultratb.py\", line 1267, in structured_traceback\n",
            "    return VerboseTB.structured_traceback(\n",
            "  File \"/usr/local/lib/python3.10/dist-packages/IPython/core/ultratb.py\", line 1142, in structured_traceback\n",
            "    formatted_exceptions += self.format_exception_as_a_whole(etype, evalue, etb, lines_of_context,\n",
            "  File \"/usr/local/lib/python3.10/dist-packages/IPython/core/ultratb.py\", line 1082, in format_exception_as_a_whole\n",
            "    last_unique, recursion_repeat = find_recursion(orig_etype, evalue, records)\n",
            "  File \"/usr/local/lib/python3.10/dist-packages/IPython/core/ultratb.py\", line 382, in find_recursion\n",
            "    return len(records), 0\n",
            "TypeError: object of type 'NoneType' has no len()\n",
            "\n",
            "During handling of the above exception, another exception occurred:\n",
            "\n",
            "Traceback (most recent call last):\n",
            "  File \"/usr/local/lib/python3.10/dist-packages/IPython/core/interactiveshell.py\", line 2099, in showtraceback\n",
            "    stb = value._render_traceback_()\n",
            "AttributeError: 'TypeError' object has no attribute '_render_traceback_'\n",
            "\n",
            "During handling of the above exception, another exception occurred:\n",
            "\n",
            "Traceback (most recent call last):\n",
            "  File \"/usr/local/lib/python3.10/dist-packages/IPython/core/ultratb.py\", line 1101, in get_records\n",
            "    return _fixed_getinnerframes(etb, number_of_lines_of_context, tb_offset)\n",
            "  File \"/usr/local/lib/python3.10/dist-packages/IPython/core/ultratb.py\", line 248, in wrapped\n",
            "    return f(*args, **kwargs)\n",
            "  File \"/usr/local/lib/python3.10/dist-packages/IPython/core/ultratb.py\", line 281, in _fixed_getinnerframes\n",
            "    records = fix_frame_records_filenames(inspect.getinnerframes(etb, context))\n",
            "  File \"/usr/lib/python3.10/inspect.py\", line 1662, in getinnerframes\n",
            "    frameinfo = (tb.tb_frame,) + getframeinfo(tb, context)\n",
            "  File \"/usr/lib/python3.10/inspect.py\", line 1620, in getframeinfo\n",
            "    filename = getsourcefile(frame) or getfile(frame)\n",
            "  File \"/usr/lib/python3.10/inspect.py\", line 829, in getsourcefile\n",
            "    module = getmodule(object, filename)\n",
            "  File \"/usr/lib/python3.10/inspect.py\", line 861, in getmodule\n",
            "    file = getabsfile(object, _filename)\n",
            "  File \"/usr/lib/python3.10/inspect.py\", line 845, in getabsfile\n",
            "    return os.path.normcase(os.path.abspath(_filename))\n",
            "  File \"/usr/lib/python3.10/posixpath.py\", line 384, in abspath\n",
            "    cwd = os.getcwd()\n",
            "OSError: [Errno 107] Transport endpoint is not connected\n"
          ]
        }
      ],
      "source": [
        "df_seriesdata['seriesdata_timestamp'] = pd.to_datetime(df_seriesdata['seriesdata_timestamp'])"
      ],
      "id": "9eec5729-574f-48ee-90c8-568d11c01bea"
    },
    {
      "cell_type": "code",
      "execution_count": null,
      "metadata": {
        "id": "e124330d-36de-43ed-b8a7-345917398366",
        "outputId": "250ad4f1-a380-401d-aa16-7fc96366a257"
      },
      "outputs": [
        {
          "data": {
            "text/plain": [
              "<pandas.core.groupby.generic.DataFrameGroupBy object at 0x00000281DDD702E0>"
            ]
          },
          "execution_count": 27,
          "metadata": {},
          "output_type": "execute_result"
        }
      ],
      "source": [],
      "id": "e124330d-36de-43ed-b8a7-345917398366"
    },
    {
      "cell_type": "code",
      "execution_count": null,
      "metadata": {
        "id": "4142b5e6-86d6-4053-9d47-25df39cbeed7"
      },
      "outputs": [],
      "source": [],
      "id": "4142b5e6-86d6-4053-9d47-25df39cbeed7"
    }
  ],
  "metadata": {
    "colab": {
      "provenance": []
    },
    "kernelspec": {
      "display_name": "Python 3 (ipykernel)",
      "language": "python",
      "name": "python3"
    },
    "language_info": {
      "codemirror_mode": {
        "name": "ipython",
        "version": 3
      },
      "file_extension": ".py",
      "mimetype": "text/x-python",
      "name": "python",
      "nbconvert_exporter": "python",
      "pygments_lexer": "ipython3",
      "version": "3.10.9"
    }
  },
  "nbformat": 4,
  "nbformat_minor": 5
}